Workbook

Sheet Overview, 20% O2
A1: Conversion mass%
B2: TEMP / FEEDSTOCK | C2: BRF500 | D2: WS500 | E2: PW500
A3: 100-end | B3: 200 (Odin) | C3: =100-'All Data, BRF500 20% O2'!E483 -> -0.24234 | D3: =100-'All Data, WS500 20% O2'!E485 -> -0.88166 | E3: =100-'All Data, PW500, 20% O2'!D485 -> -2.73219
B4: 225 (Sif) | C4: =100-'All Data, BRF500 20% O2'!L483 -> 6.05324 | D4: =100-'All Data, WS500 20% O2'!K485 -> 2.49587 | E4: =100-'All Data, PW500, 20% O2'!J485 -> -0.93103
B5: 250 (Sif) | C5: =100-'All Data, BRF500 20% O2'!Z1203 -> 18.41455 | D5: =100-'All Data, WS500 20% O2'!W1205 -> 12.50453 | E5: =100-'All Data, PW500, 20% O2'!V1205 -> -1.1356
A9: Conversion, X_C
B10: TEMP/FEEDSTOCK | C10: BRF500 | D10: WS500 | E10: PW500
B11: 200 (Odin) | C11: ='All Data, BRF500 20% O2'!F483 -> 0.0079895093 | D11: ='All Data, WS500 20% O2'!F485 -> 0.0017342515 | E11: ='All Data, PW500, 20% O2'!E485 -> 0.00059086391
B12: 225 (Sif) | C12: ='All Data, BRF500 20% O2'!M483 -> 0.10909445 | D12: ='All Data, WS500 20% O2'!L485 -> 0.034816002 | E12: ='All Data, PW500, 20% O2'!K485 -> 0.0051481576
B13: 250 (Sif) | C13: ='All Data, BRF500 20% O2'!AA1203 -> 0.31419213 | D13: ='All Data, WS500 20% O2'!X1205 -> 0.15781484 | E13: ='All Data, PW500, 20% O2'!W1205 -> 0.009912384
A16: Difference between Odin and Sif, corrected Mass%
B18: Temp/Feedstock | C18: BRF500 | D18: WS500 | E18: PW500 | F18: Mean
B19: 225 | C19: ='All Data, BRF500 20% O2'!S483-'All Data, BRF500 20% O2'!L483 -> 4.02155 | D19: ='All Data, WS500 20% O2'!Q485-'All Data, WS500 20% O2'!K485 -> 2.93008 | E19: ='All Data, PW500, 20% O2'!P485-'All Data, PW500, 20% O2'!J485 -> 2.16105 | F19: =AVERAGE(C19:E19) -> 3.03756
B20: 250 | C20: ='All Data, BRF500 20% O2'!AG1203-'All Data, BRF500 20% O2'!Z1203 -> 5.03834 | D20: ='All Data, WS500 20% O2'!AC1205-'All Data, WS500 20% O2'!W1205 -> 6.24911 | E20: ='All Data, PW500, 20% O2'!AB1205-'All Data, PW500, 20% O2'!V1205 -> 2.38273 | F20: =AVERAGE(C20:E20) -> 4.5567267

Sheet All Data, BRF500 20% O2
M1: Ash fraction: | N1: =40.08/100 -> 0.4008
C2: 200C Odin | J2: 225 Sif | Q2: 225 Odin | X2: 250 Sif | AE2: 250 Odin | AK2: Linear (1) | AQ2: Linear (2) | AW2: Linear (Real, Used)
B3: TEMP | C3: CORRECTED TIME | D3: MASS% | E3: CORRECTED MASS% | F3: X_C FROM TOP-POINT | I3: TEMP | J3: CORRECTED TIME | K3: MASS% | L3: CORRECTED MASS% | M3: X_C FROM TOP-POINT | P3: TEMP | Q3: CORRECTED TIME | R3: MASS% | S3: CORRECTED MASS% | T3: X_C FROM TOP-POINT | W3: TEMP | X3: CORRECTED TIME | Y3: MASS% | Z3: CORRECTED MASS% | AA3: X_C FROM TOP-POINT | AD3: TEMP | AE3: CORRECTED TIME | AF3: MASS% | AG3: CORRECTED MASS% | AH3: X_C FROM TOP-POINT | AK3: TEMP | AL3: TIME | AM3: MASS% | AN3: CORRECTED MASS% | AO3: X_C | AQ3: TEMP | AR3: TIME | AS3: MASS% | AT3: CORRECTED MASS% | AU3: X_C | AW3: TEMP | AX3: TIME | AY3: MASS% | AZ3: CORRECTED MASS
B4: 200.11103 | C4: 0 | D4: 98.87356 | E4: =100-($D$4-D4) -> 100 | I4: 225.00028 | J4: 0 | K4: 96.41293 | L4: =100-($K$4-K4) -> 100 | P4: 224.99323 | Q4: 0 | R4: 100.07582 | S4: =100-($R$4-R4) -> 100 | W4: 250.00303 | X4: 0 | Y4: 94.55917 | Z4: =100-($Y$4-Y4) -> 100 | AD4: 250.02995 | AE4: 0 | AF4: 99.73851 | AG4: =100-($AF$4-AF4) -> 100 | AK4: 105.19646 | AL4: 0 | AM4: 97.41378 | AN4: =100-($AM$4-AM4) -> 100 | AQ4: 106.4888 | AR4: 0 | AS4: 97.04127 | AT4: =100-($AS$4-AS4) -> 100 | AW4: 88.62146 | AX4: 0 | AY4: 98.33435 | AZ4: =100-($AY$4-AY4) -> 100
B5: 202.31092 | C5: 0.5 | D5: 98.94037 | E5: =100-($D$4-D5) -> 100.06681 | I5: 225.21155 | J5: 0.5 | K5: 96.48939 | L5: =100-($K$4-K5) -> 100.07646 | P5: 227.11912 | Q5: 0.5 | R5: 99.77134 | S5: =100-($R$4-R5) -> 99.69552 | W5: 250.2797 | X5: 0.5 | Y5: 94.69285 | Z5: =100-($Y$4-Y5) -> 100.13368 | AD5: 250.07247 | AE5: 0.5 | AF5: 99.90597 | AG5: =100-($AF$4-AF5) -> 100.16746 | AK5: 106.44304 | AL5: 0.5 | AM5: 97.47028 | AN5: =100-($AM$4-AM5) -> 100.0565 | AQ5: 108.3845 | AR5: 0.5 | AS5: 97.03598 | AT5: =100-($AS$4-AS5) -> 99.99471 | AW5: 91.15437 | AX5: 0.5 | AY5: 98.39046 | AZ5: =100-($AY$4-AY5) -> 100.05611
B6: 204.03914 | C6: 1 | D6: 99.04353 | E6: =100-($D$4-D6) -> 100.16997 | I6: 225.37519 | J6: 1 | K6: 96.64386 | L6: =100-($K$4-K6) -> 100.23093 | P6: 228.69852 | Q6: 1 | R6: 100.08382 | S6: =100-($R$4-R6) -> 100.008 | W6: 250.52506 | X6: 1 | Y6: 94.85752 | Z6: =100-($Y$4-Y6) -> 100.29835 | AD6: 250.14172 | AE6: 1 | AF6: 100.12373 | AG6: =100-($AF$4-AF6) -> 100.38522 | AK6: 108.34565 | AL6: 1 | AM6: 97.4546 | AN6: =100-($AM$4-AM6) -> 100.04082 | AQ6: 110.69308 | AR6: 1 | AS6: 97.02876 | AT6: =100-($AS$4-AS6) -> 99.98749 | AW6: 94.84196 | AX6: 1 | AY6: 98.34933 | AZ6: =100-($AY$4-AY6) -> 100.01498
B7: 205.16368 | C7: 1.5 | D7: 99.1012 | E7: =100-($D$4-D7) -> 100.22764 | I7: 225.34948 | J7: 1.5 | K7: 96.72727 | L7: =100-($K$4-K7) -> 100.31434 | P7: 229.64314 | Q7: 1.5 | R7: 100.08121 | S7: =100-($R$4-R7) -> 100.00539 | W7: 250.48583 | X7: 1.5 | Y7: 94.96108 | Z7: =100-($Y$4-Y7) -> 100.40191 | AD7: 250.17527 | AE7: 1.5 | AF7: 100.19843 | AG7: =100-($AF$4-AF7) -> 100.45992 | AK7: 110.67225 | AL7: 1.5 | AM7: 97.46064 | AN7: =100-($AM$4-AM7) -> 100.04686 | AQ7: 113.24532 | AR7: 1.5 | AS7: 97.04334 | AT7: =100-($AS$4-AS7) -> 100.00207 | AU7: =($AT$7-AT7)/($AT$7*(1-$N$1)) -> 0 | AW7: 98.92243 | AX7: 1.5 | AY7: 98.36457 | AZ7: =100-($AY$4-AY7) -> 100.03022
B8: 205.76915 | C8: 2 | D8: 99.1657 | E8: =100-($D$4-D8) -> 100.29214 | I8: 225.25546 | J8: 2 | K8: 96.80404 | L8: =100-($K$4-K8) -> 100.39111 | P8: 230.09608 | Q8: 2 | R8: 100.06466 | S8: =100-($R$4-R8) -> 99.98884 | W8: 250.35082 | X8: 2 | Y8: 95.0319 | Z8: =100-($Y$4-Y8) -> 100.47273 | AD8: 250.16636 | AE8: 2 | AF8: 100.15464 | AG8: =100-($AF$4-AF8) -> 100.41613 | AK8: 113.23278 | AL8: 2 | AM8: 97.47775 | AN8: =100-($AM$4-AM8) -> 100.06397 | AO8: =($AN$8-AN8)/($AN$8*(1-$N$1)) -> 0 | AQ8: 115.92513 | AR8: 2 | AS8: 97.03246 | AT8: =100-($AS$4-AS8) -> 99.99119 | AU8: =($AT$7-AT8)/($AT$7*(1-$N$1)) -> 0.00018157168 | AW8: 102.96055 | AX8: 2 | AY8: 98.37394 | AZ8: =100-($AY$4-AY8) -> 100.03959
B9: 206.02692 | C9: 2.5 | D9: 99.20744 | E9: =100-($D$4-D9) -> 100.33388 | I9: 225.15757 | J9: 2.5 | K9: 96.83488 | L9: =100-($K$4-K9) -> 100.42195 | P9: 230.26029 | Q9: 2.5 | R9: 100.14502 | S9: =100-($R$4-R9) -> 100.0692 | W9: 250.21381 | X9: 2.5 | Y9: 95.04537 | Z9: =100-($Y$4-Y9) -> 100.4862 | AD9: 250.13445 | AE9: 2.5 | AF9: 100.26729 | AG9: =100-($AF$4-AF9) -> 100.52878 | AH9: =($AG$9-AG9)/($AG$9*(1-$N$1)) -> 0 | AK9: 115.91846 | AL9: 2.5 | AM9: 97.46638 | AN9: =100-($AM$4-AM9) -> 100.0526 | AO9: =($AN$8-AN9)/($AN$8*(1-$N$1)) -> 0.0001896317 | AQ9: 118.6589 | AR9: 2.5 | AS9: 97.02265 | AT9: =100-($AS$4-AS9) -> 99.98138 | AU9: =($AT$7-AT9)/($AT$7*(1-$N$1)) -> 0.00034528658 | AW9: 106.68785 | AX9: 2.5 | AY9: 98.39102 | AZ9: =100-($AY$4-AY9) -> 100.05667
B10: 206.08526 | C10: 3 | D10: 99.29296 | E10: =100-($D$4-D10) -> 100.4194 | I10: 225.07777 | J10: 3 | K10: 96.83857 | L10: =100-($K$4-K10) -> 100.42564 | P10: 230.29175 | Q10: 3 | R10: 100.17519 | S10: =100-($R$4-R10) -> 100.09937 | W10: 250.10079 | X10: 3 | Y10: 95.06056 | Z10: =100-($Y$4-Y10) -> 100.50139 | AD10: 250.10866 | AE10: 3 | AF10: 100.10891 | AG10: =100-($AF$4-AF10) -> 100.3704 | AH10: =($AG$9-AG10)/($AG$9*(1-$N$1)) -> 0.0026292878 | AK10: 118.65761 | AL10: 3 | AM10: 97.46712 | AN10: =100-($AM$4-AM10) -> 100.05334 | AO10: =($AN$8-AN10)/($AN$8*(1-$N$1)) -> 0.00017728979 | AQ10: 121.41116 | AR10: 3 | AS10: 97.00079 | AT10: =100-($AS$4-AS10) -> 99.95952 | AU10: =($AT$7-AT10)/($AT$7*(1-$N$1)) -> 0.00071009879 | AW10: 110.01201 | AX10: 3 | AY10: 98.37021 | AZ10: =100-($AY$4-AY10) -> 100.03586
B11: 206.03246 | C11: 3.5 | D11: 99.25693 | E11: =100-($D$4-D11) -> 100.38337 | I11: 225.02272 | J11: 3.5 | K11: 96.88645 | L11: =100-($K$4-K11) -> 100.47352 | P11: 230.26492 | Q11: 3.5 | R11: 100.1371 | S11: =100-($R$4-R11) -> 100.06128 | W11: 250.01891 | X11: 3.5 | Y11: 95.06653 | Z11: =100-($Y$4-Y11) -> 100.50736 | AA11: =($Z$11-Z11)/($Z$11*(1-$N$1)) -> 0 | AD11: 250.09214 | AE11: 3.5 | AF11: 100.14182 | AG11: =100-($AF$4-AF11) -> 100.40331 | AH11: =($AG$9-AG11)/($AG$9*(1-$N$1)) -> 0.0020829444 | AK11: 121.41877 | AL11: 3.5 | AM11: 97.44808 | AN11: =100-($AM$4-AM11) -> 100.0343 | AO11: =($AN$8-AN11)/($AN$8*(1-$N$1)) -> 0.00049484366 | AQ11: 124.15429 | AR11: 3.5 | AS11: 96.98214 | AT11: =100-($AS$4-AS11) -> 99.94087 | AU11: =($AT$7-AT11)/($AT$7*(1-$N$1)) -> 0.0010213407 | AW11: 112.91452 | AX11: 3.5 | AY11: 98.31847 | AZ11: =100-($AY$4-AY11) -> 99.98412
B12: 205.90749 | C12: 4 | D12: 99.28542 | E12: =100-($D$4-D12) -> 100.41186 | I12: 224.98786 | J12: 4 | K12: 96.90602 | L12: =100-($K$4-K12) -> 100.49309 | P12: 230.19832 | Q12: 4 | R12: 100.1304 | S12: =100-($R$4-R12) -> 100.05458 | W12: 249.96587 | X12: 4 | Y12: 95.06433 | Z12: =100-($Y$4-Y12) -> 100.50516 | AA12: =($Z$11-Z12)/($Z$11*(1-$N$1)) -> 3.6530281e-05 | AD12: 250.07831 | AE12: 4 | AF12: 100.25499 | AG12: =100-($AF$4-AF12) -> 100.51648 | AH12: =($AG$9-AG12)/($AG$9*(1-$N$1)) -> 0.00020419396 | AK12: 124.17375 | AL12: 4 | AM12: 97.42665 | AN12: =100-($AM$4-AM12) -> 100.01287 | AO12: =($AN$8-AN12)/($AN$8*(1-$N$1)) -> 0.00085225855 | AQ12: 126.86979 | AR12: 4 | AS12: 96.97397 | AT12: =100-($AS$4-AS12) -> 99.9327 | AU12: =($AT$7-AT12)/($AT$7*(1-$N$1)) -> 0.0011576863 | AW12: 115.42709 | AX12: 4 | AY12: 98.30879 | AZ12: =100-($AY$4-AY12) -> 99.97444
B13: 205.72273 | C13: 4.5 | D13: 99.21124 | E13: =100-($D$4-D13) -> 100.33768 | I13: 224.96079 | J13: 4.5 | K13: 96.90017 | L13: =100-($K$4-K13) -> 100.48724 | P13: 230.06881 | Q13: 4.5 | R13: 100.24339 | S13: =100-($R$4-R13) -> 100.16757 | T13: =($S$13-S13)/($S$13*(1-$N$1)) -> 0 | W13: 249.94198 | X13: 4.5 | Y13: 95.05271 | Z13: =100-($Y$4-Y13) -> 100.49354 | AA13: =($Z$11-Z13)/($Z$11*(1-$N$1)) -> 0.00022947658 | AD13: 250.07072 | AE13: 4.5 | AF13: 100.13798 | AG13: =100-($AF$4-AF13) -> 100.39947 | AH13: =($AG$9-AG13)/($AG$9*(1-$N$1)) -> 0.0021466928 | AK13: 126.88092 | AL13: 4.5 | AM13: 97.42428 | AN13: =100-($AM$4-AM13) -> 100.0105 | AO13: =($AN$8-AN13)/($AN$8*(1-$N$1)) -> 0.000891786 | AQ13: 129.54726 | AR13: 4.5 | AS13: 96.94606 | AT13: =100-($AS$4-AS13) -> 99.90479 | AU13: =($AT$7-AT13)/($AT$7*(1-$N$1)) -> 0.0016234644 | AW13: 117.62746 | AX13: 4.5 | AY13: 98.29999 | AZ13: =100-($AY$4-AY13) -> 99.96564
B14: 205.48319 | C14: 5 | D14: 99.2469 | E14: =100-($D$4-D14) -> 100.37334 | I14: 224.95097 | J14: 5 | K14: 96.90252 | L14: =100-($K$4-K14) -> 100.48959 | P14: 229.86067 | Q14: 5 | R14: 99.96279 | S14: =100-($R$4-R14) -> 99.88697 | T14: =($S$13-S14)/($S$13*(1-$N$1)) -> 0.0046750765 | W14: 249.93098 | X14: 5 | Y14: 95.03162 | Z14: =100-($Y$4-Y14) -> 100.47245 | AA14: =($Z$11-Z14)/($Z$11*(1-$N$1)) -> 0.00057966914 | AD14: 250.05874 | AE14: 5 | AF14: 100.17148 | AG14: =100-($AF$4-AF14) -> 100.43297 | AH14: =($AG$9-AG14)/($AG$9*(1-$N$1)) -> 0.0015905548 | AK14: 129.54263 | AL14: 5 | AM14: 97.40017 | AN14: =100-($AM$4-AM14) -> 99.98639 | AO14: =($AN$8-AN14)/($AN$8*(1-$N$1)) -> 0.0012938986 | AQ14: 132.16341 | AR14: 5 | AS14: 96.93957 | AT14: =100-($AS$4-AS14) -> 99.8983 | AU14: =($AT$7-AT14)/($AT$7*(1-$N$1)) -> 0.0017317732 | AW14: 119.57439 | AX14: 5 | AY14: 98.29122 | AZ14: =100-($AY$4-AY14) -> 99.95687
B15: 205.18277 | C15: 5.5 | D15: 99.17901 | E15: =100-($D$4-D15) -> 100.30545 | I15: 224.949 | J15: 5.5 | K15: 96.93046 | L15: =100-($K$4-K15) -> 100.51753 | M15: =($L$15-L15)/($L$15*(1-$N$1)) -> 0 | P15: 229.58063 | Q15: 5.5 | R15: 100.04909 | S15: =100-($R$4-R15) -> 99.97327 | T15: =($S$13-S15)/($S$13*(1-$N$1)) -> 0.0032372322 | W15: 249.921 | X15: 5.5 | Y15: 95.01273 | Z15: =100-($Y$4-Y15) -> 100.45356 | AA15: =($Z$11-Z15)/($Z$11*(1-$N$1)) -> 0.00089333141 | AD15: 250.04787 | AE15: 5.5 | AF15: 100.15102 | AG15: =100-($AF$4-AF15) -> 100.41251 | AH15: =($AG$9-AG15)/($AG$9*(1-$N$1)) -> 0.001930214 | AK15: 132.15598 | AL15: 5.5 | AM15: 97.3983 | AN15: =100-($AM$4-AM15) -> 99.98452 | AO15: =($AN$8-AN15)/($AN$8*(1-$N$1)) -> 0.0013250869 | AQ15: 134.76291 | AR15: 5.5 | AS15: 96.9154 | AT15: =100-($AS$4-AS15) -> 99.87413 | AU15: =($AT$7-AT15)/($AT$7*(1-$N$1)) -> 0.002135136 | AW15: 121.35183 | AX15: 5.5 | AY15: 98.23736 | AZ15: =100-($AY$4-AY15) -> 99.90301
B16: 204.8312 | C16: 6 | D16: 99.22138 | E16: =100-($D$4-D16) -> 100.34782 | I16: 224.95199 | J16: 6 | K16: 96.90783 | L16: =100-($K$4-K16) -> 100.4949 | M16: =($L$15-L16)/($L$15*(1-$N$1)) -> 0.00037572573 | P16: 229.24639 | Q16: 6 | R16: 100.13445 | S16: =100-($R$4-R16) -> 100.05863 | T16: =($S$13-S16)/($S$13*(1-$N$1)) -> 0.0018150493 | W16: 249.92002 | X16: 6 | Y16: 94.99167 | Z16: =100-($Y$4-Y16) -> 100.4325 | AA16: =($Z$11-Z16)/($Z$11*(1-$N$1)) -> 0.0012430258 | AD16: 250.03592 | AE16: 6 | AF16: 100.0791 | AG16: =100-($AF$4-AF16) -> 100.34059 | AH16: =($AG$9-AG16)/($AG$9*(1-$N$1)) -> 0.0031241676 | AK16: 134.77178 | AL16: 6 | AM16: 97.36975 | AN16: =100-($AM$4-AM16) -> 99.95597 | AO16: =($AN$8-AN16)/($AN$8*(1-$N$1)) -> 0.0018012509 | AQ16: 137.35828 | AR16: 6 | AS16: 96.86451 | AT16: =100-($AS$4-AS16) -> 99.82324 | AU16: =($AT$7-AT16)/($AT$7*(1-$N$1)) -> 0.0029844175 | AW16: 122.99551 | AX16: 6 | AY16: 98.23643 | AZ16: =100-($AY$4-AY16) -> 99.90208
B17: 204.44404 | C17: 6.5 | D17: 99.27847 | E17: =100-($D$4-D17) -> 100.40491 | I17: 224.95696 | J17: 6.5 | K17: 96.89159 | L17: =100-($K$4-K17) -> 100.47866 | M17: =($L$15-L17)/($L$15*(1-$N$1)) -> 0.00064535834 | P17: 228.88248 | Q17: 6.5 | R17: 100.00054 | S17: =100-($R$4-R17) -> 99.92472 | T17: =($S$13-S17)/($S$13*(1-$N$1)) -> 0.0040461238 | W17: 249.93305 | X17: 6.5 | Y17: 94.96101 | Z17: =100-($Y$4-Y17) -> 100.40184 | AA17: =($Z$11-Z17)/($Z$11*(1-$N$1)) -> 0.0017521251 | AD17: 250.02595 | AE17: 6.5 | AF17: 100.2091 | AG17: =100-($AF$4-AF17) -> 100.47059 | AH17: =($AG$9-AG17)/($AG$9*(1-$N$1)) -> 0.00096602005 | AK17: 137.36559 | AL17: 6.5 | AM17: 97.34054 | AN17: =100-($AM$4-AM17) -> 99.92676 | AO17: =($AN$8-AN17)/($AN$8*(1-$N$1)) -> 0.0022884226 | AQ17: 139.92604 | AR17: 6.5 | AS17: 96.87001 | AT17: =100-($AS$4-AS17) -> 99.82874 | AU17: =($AT$7-AT17)/($AT$7*(1-$N$1)) -> 0.0028926304 | AW17: 124.56314 | AX17: 6.5 | AY17: 98.2038 | AZ17: =100-($AY$4-AY17) -> 99.86945
B18: 204.04245 | C18: 7 | D18: 99.30095 | E18: =100-($D$4-D18) -> 100.42739 | I18: 224.96493 | J18: 7 | K18: 96.92444 | L18: =100-($K$4-K18) -> 100.51151 | M18: =($L$15-L18)/($L$15*(1-$N$1)) -> 9.9950018e-05 | P18: 228.51753 | Q18: 7 | R18: 100.1945 | S18: =100-($R$4-R18) -> 100.11868 | T18: =($S$13-S18)/($S$13*(1-$N$1)) -> 0.00081455628 | W18: 249.93805 | X18: 7 | Y18: 94.9551 | Z18: =100-($Y$4-Y18) -> 100.39593 | AA18: =($Z$11-Z18)/($Z$11*(1-$N$1)) -> 0.0018502587 | AD18: 250.02297 | AE18: 7 | AF18: 100.06921 | AG18: =100-($AF$4-AF18) -> 100.3307 | AH18: =($AG$9-AG18)/($AG$9*(1-$N$1)) -> 0.0032883528 | AK18: 139.9297 | AL18: 7 | AM18: 97.33466 | AN18: =100-($AM$4-AM18) -> 99.92088 | AO18: =($AN$8-AN18)/($AN$8*(1-$N$1)) -> 0.0023864907 | AQ18: 142.4575 | AR18: 7 | AS18: 96.84602 | AT18: =100-($AS$4-AS18) -> 99.80475 | AU18: =($AT$7-AT18)/($AT$7*(1-$N$1)) -> 0.0032929892 | AW18: 126.08906 | AX18: 7 | AY18: 98.18548 | AZ18: =100-($AY$4-AY18) -> 99.85113
B19: 203.6442 | C19: 7.5 | D19: 99.32027 | E19: =100-($D$4-D19) -> 100.44671 | I19: 224.96706 | J19: 7.5 | K19: 96.90278 | L19: =100-($K$4-K19) -> 100.48985 | M19: =($L$15-L19)/($L$15*(1-$N$1)) -> 0.00045957085 | P19: 228.17219 | Q19: 7.5 | R19: 100.10457 | S19: =100-($R$4-R19) -> 100.02875 | T19: =($S$13-S19)/($S$13*(1-$N$1)) -> 0.00231288 | W19: 249.94702 | X19: 7.5 | Y19: 94.93593 | Z19: =100-($Y$4-Y19) -> 100.37676 | AA19: =($Z$11-Z19)/($Z$11*(1-$N$1)) -> 0.0021685703 | AD19: 250.01794 | AE19: 7.5 | AF19: 100.11503 | AG19: =100-($AF$4-AF19) -> 100.37652 | AH19: =($AG$9-AG19)/($AG$9*(1-$N$1)) -> 0.0025276888 | AK19: 142.45761 | AL19: 7.5 | AM19: 97.3109 | AN19: =100-($AM$4-AM19) -> 99.89712 | AO19: =($AN$8-AN19)/($AN$8*(1-$N$1)) -> 0.0027827659 | AQ19: 144.99693 | AR19: 7.5 | AS19: 96.8251 | AT19: =100-($AS$4-AS19) -> 99.78383 | AU19: =($AT$7-AT19)/($AT$7*(1-$N$1)) -> 0.0036421142 | AW19: 127.59048 | AX19: 7.5 | AY19: 98.20108 | AZ19: =100-($AY$4-AY19) -> 99.86673
B20: 203.27386 | C20: 8 | D20: 99.37332 | E20: =100-($D$4-D20) -> 100.49976 | I20: 224.97107 | J20: 8 | K20: 96.89664 | L20: =100-($K$4-K20) -> 100.48371 | M20: =($L$15-L20)/($L$15*(1-$N$1)) -> 0.00056151323 | P20: 227.84817 | Q20: 8 | R20: 99.99582 | S20: =100-($R$4-R20) -> 99.92 | T20: =($S$13-S20)/($S$13*(1-$N$1)) -> 0.0041247637 | W20: 249.95301 | X20: 8 | Y20: 94.90531 | Z20: =100-($Y$4-Y20) -> 100.34614 | AA20: =($Z$11-Z20)/($Z$11*(1-$N$1)) -> 0.0026770054 | AD20: 250.00979 | AE20: 8 | AF20: 100.11665 | AG20: =100-($AF$4-AF20) -> 100.37814 | AH20: =($AG$9-AG20)/($AG$9*(1-$N$1)) -> 0.002500795 | AK20: 145.00374 | AL20: 8 | AM20: 97.30154 | AN20: =100-($AM$4-AM20) -> 99.88776 | AO20: =($AN$8-AN20)/($AN$8*(1-$N$1)) -> 0.0029388743 | AQ20: 147.55415 | AR20: 8 | AS20: 96.80696 | AT20: =100-($AS$4-AS20) -> 99.76569 | AU20: =($AT$7-AT20)/($AT$7*(1-$N$1)) -> 0.0039448449 | AW20: 129.05264 | AX20: 8 | AY20: 98.1492 | AZ20: =100-($AY$4-AY20) -> 99.81485
B21: 202.93733 | C21: 8.5 | D21: 99.36734 | E21: =100-($D$4-D21) -> 100.49378 | I21: 224.97413 | J21: 8.5 | K21: 96.86986 | L21: =100-($K$4-K21) -> 100.45693 | M21: =($L$15-L21)/($L$15*(1-$N$1)) -> 0.0010061414 | P21: 227.54402 | Q21: 8.5 | R21: 99.97807 | S21: =100-($R$4-R21) -> 99.90225 | T21: =($S$13-S21)/($S$13*(1-$N$1)) -> 0.0044204964 | W21: 249.95798 | X21: 8.5 | Y21: 94.8861 | Z21: =100-($Y$4-Y21) -> 100.32693 | AA21: =($Z$11-Z21)/($Z$11*(1-$N$1)) -> 0.0029959812 | AD21: 250.01223 | AE21: 8.5 | AF21: 100.03751 | AG21: =100-($AF$4-AF21) -> 100.299 | AH21: =($AG$9-AG21)/($AG$9*(1-$N$1)) -> 0.0038146088 | AK21: 147.55356 | AL21: 8.5 | AM21: 97.28672 | AN21: =100-($AM$4-AM21) -> 99.87294 | AO21: =($AN$8-AN21)/($AN$8*(1-$N$1)) -> 0.003186046 | AQ21: 150.07486 | AR21: 8.5 | AS21: 96.80087 | AT21: =100-($AS$4-AS21) -> 99.7596 | AU21: =($AT$7-AT21)/($AT$7*(1-$N$1)) -> 0.0040464783 | AW21: 130.51246 | AX21: 8.5 | AY21: 98.13406 | AZ21: =100-($AY$4-AY21) -> 99.79971
B22: 202.62302 | C22: 9 | D22: 99.2993 | E22: =100-($D$4-D22) -> 100.42574 | I22: 224.98101 | J22: 9 | K22: 96.88608 | L22: =100-($K$4-K22) -> 100.47315 | M22: =($L$15-L22)/($L$15*(1-$N$1)) -> 0.00073684083 | P22: 227.26118 | Q22: 9 | R22: 100.00992 | S22: =100-($R$4-R22) -> 99.9341 | T22: =($S$13-S22)/($S$13*(1-$N$1)) -> 0.0038898436 | W22: 249.964 | X22: 9 | Y22: 94.842 | Z22: =100-($Y$4-Y22) -> 100.28283 | AA22: =($Z$11-Z22)/($Z$11*(1-$N$1)) -> 0.0037282472 | AD22: 250.0109 | AE22: 9 | AF22: 100.12275 | AG22: =100-($AF$4-AF22) -> 100.38424 | AH22: =($AG$9-AG22)/($AG$9*(1-$N$1)) -> 0.0023995281 | AK22: 150.06545 | AL22: 9 | AM22: 97.27548 | AN22: =100-($AM$4-AM22) -> 99.8617 | AO22: =($AN$8-AN22)/($AN$8*(1-$N$1)) -> 0.0033735095 | AQ22: 152.59187 | AR22: 9 | AS22: 96.77562 | AT22: =100-($AS$4-AS22) -> 99.73435 | AU22: =($AT$7-AT22)/($AT$7*(1-$N$1)) -> 0.0044678648 | AW22: 131.9788 | AX22: 9 | AY22: 98.18388 | AZ22: =100-($AY$4-AY22) -> 99.84953
B23: 202.3154 | C23: 9.5 | D23: 99.34893 | E23: =100-($D$4-D23) -> 100.47537 | I23: 224.98102 | J23: 9.5 | K23: 96.84585 | L23: =100-($K$4-K23) -> 100.43292 | M23: =($L$15-L23)/($L$15*(1-$N$1)) -> 0.0014047792 | P23: 226.99897 | Q23: 9.5 | R23: 99.96701 | S23: =100-($R$4-R23) -> 99.89119 | T23: =($S$13-S23)/($S$13*(1-$N$1)) -> 0.0046047671 | W23: 249.96902 | X23: 9.5 | Y23: 94.83052 | Z23: =100-($Y$4-Y23) -> 100.27135 | AA23: =($Z$11-Z23)/($Z$11*(1-$N$1)) -> 0.0039188689 | AD23: 250.01215 | AE23: 9.5 | AF23: 100.08249 | AG23: =100-($AF$4-AF23) -> 100.34398 | AH23: =($AG$9-AG23)/($AG$9*(1-$N$1)) -> 0.0030678898 | AK23: 152.60161 | AL23: 9.5 | AM23: 97.24487 | AN23: =100-($AM$4-AM23) -> 99.83109 | AO23: =($AN$8-AN23)/($AN$8*(1-$N$1)) -> 0.0038840307 | AQ23: 155.14275 | AR23: 9.5 | AS23: 96.75465 | AT23: =100-($AS$4-AS23) -> 99.71338 | AU23: =($AT$7-AT23)/($AT$7*(1-$N$1)) -> 0.0048178242 | AW23: 133.45459 | AX23: 9.5 | AY23: 98.12264 | AZ23: =100-($AY$4-AY23) -> 99.78829
B24: 202.00354 | C24: 10 | D24: 99.33731 | E24: =100-($D$4-D24) -> 100.46375 | I24: 224.98217 | J24: 10 | K24: 96.84837 | L24: =100-($K$4-K24) -> 100.43544 | M24: =($L$15-L24)/($L$15*(1-$N$1)) -> 0.0013629397 | P24: 226.75583 | Q24: 10 | R24: 100.15365 | S24: =100-($R$4-R24) -> 100.07783 | T24: =($S$13-S24)/($S$13*(1-$N$1)) -> 0.0014951581 | W24: 249.97203 | X24: 10 | Y24: 94.78831 | Z24: =100-($Y$4-Y24) -> 100.22914 | AA24: =($Z$11-Z24)/($Z$11*(1-$N$1)) -> 0.0046197521 | AD24: 250.00521 | AE24: 10 | AF24: 99.99152 | AG24: =100-($AF$4-AF24) -> 100.25301 | AH24: =($AG$9-AG24)/($AG$9*(1-$N$1)) -> 0.004578095 | AK24: 155.15547 | AL24: 10 | AM24: 97.23329 | AN24: =100-($AM$4-AM24) -> 99.81951 | AO24: =($AN$8-AN24)/($AN$8*(1-$N$1)) -> 0.0040771649 | AQ24: 157.66635 | AR24: 10 | AS24: 96.72332 | AT24: =100-($AS$4-AS24) -> 99.68205 | AU24: =($AT$7-AT24)/($AT$7*(1-$N$1)) -> 0.0053406772 | AW24: 134.94895 | AX24: 10 | AY24: 98.12039 | AZ24: =100-($AY$4-AY24) -> 99.78604
B25: 201.69974 | C25: 10.5 | D25: 99.42151 | E25: =100-($D$4-D25) -> 100.54795 | I25: 224.98204 | J25: 10.5 | K25: 96.83704 | L25: =100-($K$4-K25) -> 100.42411 | M25: =($L$15-L25)/($L$15*(1-$N$1)) -> 0.0015510516 | P25: 226.5316 | Q25: 10.5 | R25: 100.02082 | S25: =100-($R$4-R25) -> 99.945 | T25: =($S$13-S25)/($S$13*(1-$N$1)) -> 0.0037082387 | W25: 249.97401 | X25: 10.5 | Y25: 94.77096 | Z25: =100-($Y$4-Y25) -> 100.21179 | AA25: =($Z$11-Z25)/($Z$11*(1-$N$1)) -> 0.0049078432 | AD25: 250.00295 | AE25: 10.5 | AF25: 100.05369 | AG25: =100-($AF$4-AF25) -> 100.31518 | AH25: =($AG$9-AG25)/($AG$9*(1-$N$1)) -> 0.0035460025 | AK25: 157.66666 | AL25: 10.5 | AM25: 97.2096 | AN25: =100-($AM$4-AM25) -> 99.79582 | AO25: =($AN$8-AN25)/($AN$8*(1-$N$1)) -> 0.0044722726 | AQ25: 160.17914 | AR25: 10.5 | AS25: 96.71634 | AT25: =100-($AS$4-AS25) -> 99.67507 | AU25: =($AT$7-AT25)/($AT$7*(1-$N$1)) -> 0.0054571634 | AW25: 136.43742 | AX25: 10.5 | AY25: 98.07801 | AZ25: =100-($AY$4-AY25) -> 99.74366
B26: 201.42119 | C26: 11 | D26: 99.44385 | E26: =100-($D$4-D26) -> 100.57029 | I26: 224.98599 | J26: 11 | K26: 96.82519 | L26: =100-($K$4-K26) -> 100.41226 | M26: =($L$15-L26)/($L$15*(1-$N$1)) -> 0.0017477971 | P26: 226.32705 | Q26: 11 | R26: 99.98817 | S26: =100-($R$4-R26) -> 99.91235 | T26: =($S$13-S26)/($S$13*(1-$N$1)) -> 0.0042522203 | W26: 249.98004 | X26: 11 | Y26: 94.74427 | Z26: =100-($Y$4-Y26) -> 100.1851 | AA26: =($Z$11-Z26)/($Z$11*(1-$N$1)) -> 0.0053510219 | AD26: 250.00106 | AE26: 11 | AF26: 100.01926 | AG26: =100-($AF$4-AF26) -> 100.28075 | AH26: =($AG$9-AG26)/($AG$9*(1-$N$1)) -> 0.0041175795 | AK26: 160.18561 | AL26: 11 | AM26: 97.20346 | AN26: =100-($AM$4-AM26) -> 99.78968 | AO26: =($AN$8-AN26)/($AN$8*(1-$N$1)) -> 0.0045746771 | AQ26: 162.7096 | AR26: 11 | AS26: 96.67472 | AT26: =100-($AS$4-AS26) -> 99.63345 | AU26: =($AT$7-AT26)/($AT$7*(1-$N$1)) -> 0.0061517418 | AW26: 137.93784 | AX26: 11 | AY26: 98.09737 | AZ26: =100-($AY$4-AY26) -> 99.76302
... B118: 200.08773 | C118: 57 | D118: 99.45286 | E118: =100-($D$4-D118) -> 100.5793 | I118: 225.00989 | J118: 57 | K118: 95.19295 | L118: =100-($K$4-K118) -> 98.78002 | M118: =($L$15-L118)/($L$15*(1-$N$1)) -> 0.028847867 | P118: 225.01034 | Q118: 57 | R118: 99.65167 | S118: =100-($R$4-R118) -> 99.57585 | T118: =($S$13-S118)/($S$13*(1-$N$1)) -> 0.0098586468 | W118: 250.00101 | X118: 57 | Y118: 92.12104 | Z118: =100-($Y$4-Y118) -> 97.56187 | AA118: =($Z$11-Z118)/($Z$11*(1-$N$1)) -> 0.048908899 | AD118: 250.02867 | AE118: 57 | AF118: 98.52201 | AG118: =100-($AF$4-AF118) -> 98.7835 | AH118: =($AG$9-AG118)/($AG$9*(1-$N$1)) -> 0.028973629 | AK118: 389.65273 | AL118: 57 | AM118: 57.61755 | AN118: =100-($AM$4-AM118) -> 60.20377 | AO118: =($AN$8-AN118)/($AN$8*(1-$N$1)) -> 0.66479836 | AQ118: 392.27148 | AR118: 57 | AS118: 53.28092 | AT118: =100-($AS$4-AS118) -> 56.23965 | AU118: =($AT$7-AT118)/($AT$7*(1-$N$1)) -> 0.73033235 | AW118: 276.21235 | AX118: 57 | AY118: 95.9223 | AZ118: =100-($AY$4-AY118) -> 97.58795
B119: 200.07603 | C119: 57.5 | D119: 99.5981 | E119: =100-($D$4-D119) -> 100.72454 | F119: =($E$119-E119)/($E$119*(1-$N$1)) -> 0 | I119: 225.00395 | J119: 57.5 | K119: 95.15299 | L119: =100-($K$4-K119) -> 98.74006 | M119: =($L$15-L119)/($L$15*(1-$N$1)) -> 0.029511322 | P119: 225.00906 | Q119: 57.5 | R119: 99.76254 | S119: =100-($R$4-R119) -> 99.68672 | T119: =($S$13-S119)/($S$13*(1-$N$1)) -> 0.0080114417 | W119: 250.00101 | X119: 57.5 | Y119: 92.09238 | Z119: =100-($Y$4-Y119) -> 97.53321 | AA119: =($Z$11-Z119)/($Z$11*(1-$N$1)) -> 0.049384788 | AD119: 250.02501 | AE119: 57.5 | AF119: 98.49688 | AG119: =100-($AF$4-AF119) -> 98.75837 | AH119: =($AG$9-AG119)/($AG$9*(1-$N$1)) -> 0.029390816 | AK119: 392.26526 | AL119: 57.5 | AM119: 56.99851 | AN119: =100-($AM$4-AM119) -> 59.58473 | AO119: =($AN$8-AN119)/($AN$8*(1-$N$1)) -> 0.67512286 | AQ119: 394.90102 | AR119: 57.5 | AS119: 52.70881 | AT119: =100-($AS$4-AS119) -> 55.66754 | AU119: =($AT$7-AT119)/($AT$7*(1-$N$1)) -> 0.73988004 | AW119: 277.71877 | AX119: 57.5 | AY119: 95.87076 | AZ119: =100-($AY$4-AY119) -> 97.53641
B120: 200.05831 | C120: 58 | D120: 99.40506 | E120: =100-($D$4-D120) -> 100.5315 | F120: =($E$119-E120)/($E$119*(1-$N$1)) -> 0.0031984548 | I120: 225.00814 | J120: 58 | K120: 95.12554 | L120: =100-($K$4-K120) -> 98.71261 | M120: =($L$15-L120)/($L$15*(1-$N$1)) -> 0.029967074 | P120: 225.00844 | Q120: 58 | R120: 99.63422 | S120: =100-($R$4-R120) -> 99.5584 | T120: =($S$13-S120)/($S$13*(1-$N$1)) -> 0.010149381 | W120: 249.999 | X120: 58 | Y120: 92.06362 | Z120: =100-($Y$4-Y120) -> 97.50445 | AA120: =($Z$11-Z120)/($Z$11*(1-$N$1)) -> 0.049862339 | AD120: 250.02322 | AE120: 58 | AF120: 98.48019 | AG120: =100-($AF$4-AF120) -> 98.74168 | AH120: =($AG$9-AG120)/($AG$9*(1-$N$1)) -> 0.029667888 | AK120: 394.89294 | AL120: 58 | AM120: 56.45112 | AN120: =100-($AM$4-AM120) -> 59.03734 | AO120: =($AN$8-AN120)/($AN$8*(1-$N$1)) -> 0.68425237 | AQ120: 397.53754 | AR120: 58 | AS120: 52.14488 | AT120: =100-($AS$4-AS120) -> 55.10361 | AU120: =($AT$7-AT120)/($AT$7*(1-$N$1)) -> 0.74929123 | AW120: 279.22376 | AX120: 58 | AY120: 95.76319 | AZ120: =100-($AY$4-AY120) -> 97.42884
B121: 200.03953 | C121: 58.5 | D121: 99.53814 | E121: =100-($D$4-D121) -> 100.66458 | F121: =($E$119-E121)/($E$119*(1-$N$1)) -> 0.00099346947 | I121: 225.00498 | J121: 58.5 | K121: 95.09018 | L121: =100-($K$4-K121) -> 98.67725 | M121: =($L$15-L121)/($L$15*(1-$N$1)) -> 0.030554156 | P121: 225.00845 | Q121: 58.5 | R121: 99.57185 | S121: =100-($R$4-R121) -> 99.49603 | T121: =($S$13-S121)/($S$13*(1-$N$1)) -> 0.011188528 | W121: 249.99798 | X121: 58.5 | Y121: 92.03115 | Z121: =100-($Y$4-Y121) -> 97.47198 | AA121: =($Z$11-Z121)/($Z$11*(1-$N$1)) -> 0.050401493 | AD121: 250.01736 | AE121: 58.5 | AF121: 98.49702 | AG121: =100-($AF$4-AF121) -> 98.75851 | AH121: =($AG$9-AG121)/($AG$9*(1-$N$1)) -> 0.029388491 | AK121: 397.53352 | AL121: 58.5 | AM121: 55.90093 | AN121: =100-($AM$4-AM121) -> 58.48715 | AO121: =($AN$8-AN121)/($AN$8*(1-$N$1)) -> 0.69342858 | AQ121: 400.18497 | AR121: 58.5 | AS121: 51.54977 | AT121: =100-($AS$4-AS121) -> 54.5085 | AU121: =($AT$7-AT121)/($AT$7*(1-$N$1)) -> 0.75922277 | AW121: 280.72373 | AX121: 58.5 | AY121: 95.64382 | AZ121: =100-($AY$4-AY121) -> 97.30947
B122: 200.02089 | C122: 59 | D122: 99.44932 | E122: =100-($D$4-D122) -> 100.57576 | F122: =($E$119-E122)/($E$119*(1-$N$1)) -> 0.0024651165 | I122: 225.00403 | J122: 59 | K122: 95.07991 | L122: =100-($K$4-K122) -> 98.66698 | M122: =($L$15-L122)/($L$15*(1-$N$1)) -> 0.030724669 | P122: 225.00897 | Q122: 59 | R122: 99.61558 | S122: =100-($R$4-R122) -> 99.53976 | T122: =($S$13-S122)/($S$13*(1-$N$1)) -> 0.010459942 | W122: 250.00499 | X122: 59 | Y122: 92.00783 | Z122: =100-($Y$4-Y122) -> 97.44866 | AA122: =($Z$11-Z122)/($Z$11*(1-$N$1)) -> 0.050788714 | AD122: 250.01335 | AE122: 59 | AF122: 98.55151 | AG122: =100-($AF$4-AF122) -> 98.813 | AH122: =($AG$9-AG122)/($AG$9*(1-$N$1)) -> 0.028483896 | AK122: 400.17559 | AL122: 59 | AM122: 55.34517 | AN122: =100-($AM$4-AM122) -> 57.93139 | AO122: =($AN$8-AN122)/($AN$8*(1-$N$1)) -> 0.70269768 | AQ122: 402.84068 | AR122: 59 | AS122: 50.92669 | AT122: =100-($AS$4-AS122) -> 53.88542 | AU122: =($AT$7-AT122)/($AT$7*(1-$N$1)) -> 0.76962108 | AW122: 282.21865 | AX122: 59 | AY122: 95.53121 | AZ122: =100-($AY$4-AY122) -> 97.19686
B123: 200.01053 | C123: 59.5 | D123: 99.43513 | E123: =100-($D$4-D123) -> 100.56157 | F123: =($E$119-E123)/($E$119*(1-$N$1)) -> 0.0027002288 | I123: 225.00712 | J123: 59.5 | K123: 95.06715 | L123: =100-($K$4-K123) -> 98.65422 | M123: =($L$15-L123)/($L$15*(1-$N$1)) -> 0.030936523 | P123: 225.00913 | Q123: 59.5 | R123: 99.51608 | S123: =100-($R$4-R123) -> 99.44026 | T123: =($S$13-S123)/($S$13*(1-$N$1)) -> 0.012117712 | W123: 250.002 | X123: 59.5 | Y123: 91.98675 | Z123: =100-($Y$4-Y123) -> 97.42758 | AA123: =($Z$11-Z123)/($Z$11*(1-$N$1)) -> 0.05113874 | AD123: 250.01414 | AE123: 59.5 | AF123: 98.43694 | AG123: =100-($AF$4-AF123) -> 98.69843 | AH123: =($AG$9-AG123)/($AG$9*(1-$N$1)) -> 0.030385888 | AK123: 402.82135 | AL123: 59.5 | AM123: 54.77877 | AN123: =100-($AM$4-AM123) -> 57.36499 | AO123: =($AN$8-AN123)/($AN$8*(1-$N$1)) -> 0.71214424 | AQ123: 405.51541 | AR123: 59.5 | AS123: 50.26012 | AT123: =100-($AS$4-AS123) -> 53.21885 | AU123: =($AT$7-AT123)/($AT$7*(1-$N$1)) -> 0.78074519 | AW123: 283.71973 | AX123: 59.5 | AY123: 95.40318 | AZ123: =100-($AY$4-AY123) -> 97.06883
B124: 199.99806 | C124: 60 | D124: 99.3712 | E124: =100-($D$4-D124) -> 100.49764 | F124: =($E$119-E124)/($E$119*(1-$N$1)) -> 0.0037594767 | I124: 225.00793 | J124: 60 | K124: 95.04722 | L124: =100-($K$4-K124) -> 98.63429 | M124: =($L$15-L124)/($L$15*(1-$N$1)) -> 0.031267421 | P124: 225.0086 | Q124: 60 | R124: 99.65853 | S124: =100-($R$4-R124) -> 99.58271 | T124: =($S$13-S124)/($S$13*(1-$N$1)) -> 0.0097443523 | W124: 250.00402 | X124: 60 | Y124: 91.93507 | Z124: =100-($Y$4-Y124) -> 97.3759 | AA124: =($Z$11-Z124)/($Z$11*(1-$N$1)) -> 0.05199687 | AD124: 250.01583 | AE124: 60 | AF124: 98.53243 | AG124: =100-($AF$4-AF124) -> 98.79392 | AH124: =($AG$9-AG124)/($AG$9*(1-$N$1)) -> 0.028800645 | AK124: 405.47923 | AL124: 60 | AM124: 54.14224 | AN124: =100-($AM$4-AM124) -> 56.72846 | AO124: =($AN$8-AN124)/($AN$8*(1-$N$1)) -> 0.72276045 | AQ124: 408.21067 | AR124: 60 | AS124: 49.36901 | AT124: =100-($AS$4-AS124) -> 52.32774 | AU124: =($AT$7-AT124)/($AT$7*(1-$N$1)) -> 0.79561654 | AW124: 285.22144 | AX124: 60 | AY124: 95.30445 | AZ124: =100-($AY$4-AY124) -> 96.9701
B125: 199.98267 | C125: 60.5 | D125: 99.4409 | E125: =100-($D$4-D125) -> 100.56734 | F125: =($E$119-E125)/($E$119*(1-$N$1)) -> 0.0026046264 | I125: 225.01075 | J125: 60.5 | K125: 95.03926 | L125: =100-($K$4-K125) -> 98.62633 | M125: =($L$15-L125)/($L$15*(1-$N$1)) -> 0.031399581 | P125: 225.01283 | Q125: 60.5 | R125: 99.59791 | S125: =100-($R$4-R125) -> 99.52209 | T125: =($S$13-S125)/($S$13*(1-$N$1)) -> 0.010754342 | W125: 250.00001 | X125: 60.5 | Y125: 91.92553 | Z125: =100-($Y$4-Y125) -> 97.36636 | AA125: =($Z$11-Z125)/($Z$11*(1-$N$1)) -> 0.052155278 | AD125: 250.01558 | AE125: 60.5 | AF125: 98.5309 | AG125: =100-($AF$4-AF125) -> 98.79239 | AH125: =($AG$9-AG125)/($AG$9*(1-$N$1)) -> 0.028826045 | AK125: 408.16633 | AL125: 60.5 | AM125: 53.39955 | AN125: =100-($AM$4-AM125) -> 55.98577 | AO125: =($AN$8-AN125)/($AN$8*(1-$N$1)) -> 0.73514722 | AQ125: 410.90384 | AR125: 60.5 | AS125: 48.37764 | AT125: =100-($AS$4-AS125) -> 51.33637 | AU125: =($AT$7-AT125)/($AT$7*(1-$N$1)) -> 0.81216109 | AW125: 286.72413 | AX125: 60.5 | AY125: 95.14492 | AZ125: =100-($AY$4-AY125) -> 96.81057
B126: 199.96881 | C126: 61 | D126: 99.49922 | E126: =100-($D$4-D126) -> 100.62566 | F126: =($E$119-E126)/($E$119*(1-$N$1)) -> 0.0016383299 | I126: 225.00692 | J126: 61 | K126: 94.99019 | L126: =100-($K$4-K126) -> 98.57726 | M126: =($L$15-L126)/($L$15*(1-$N$1)) -> 0.032214289 | P126: 225.01454 | Q126: 61 | R126: 99.58735 | S126: =100-($R$4-R126) -> 99.51153 | T126: =($S$13-S126)/($S$13*(1-$N$1)) -> 0.010930282 | W126: 250.00502 | X126: 61 | Y126: 91.90248 | Z126: =100-($Y$4-Y126) -> 97.34331 | AA126: =($Z$11-Z126)/($Z$11*(1-$N$1)) -> 0.052538016 | AD126: 250.01374 | AE126: 61 | AF126: 98.35024 | AG126: =100-($AF$4-AF126) -> 98.61173 | AH126: =($AG$9-AG126)/($AG$9*(1-$N$1)) -> 0.031825206 | AK126: 410.84969 | AL126: 61 | AM126: 52.47629 | AN126: =100-($AM$4-AM126) -> 55.06251 | AO126: =($AN$8-AN126)/($AN$8*(1-$N$1)) -> 0.75054558 | AQ126: 413.51143 | AR126: 61 | AS126: 47.23423 | AT126: =100-($AS$4-AS126) -> 50.19296 | AU126: =($AT$7-AT126)/($AT$7*(1-$N$1)) -> 0.83124297 | AW126: 288.22561 | AX126: 61 | AY126: 94.91824 | AZ126: =100-($AY$4-AY126) -> 96.58389
B127: 199.95649 | C127: 61.5 | D127: 99.44335 | E127: =100-($D$4-D127) -> 100.56979 | F127: =($E$119-E127)/($E$119*(1-$N$1)) -> 0.0025640327 | I127: 225.00482 | J127: 61.5 | K127: 94.97361 | L127: =100-($K$4-K127) -> 98.56068 | M127: =($L$15-L127)/($L$15*(1-$N$1)) -> 0.032489567 | P127: 225.01411 | Q127: 61.5 | R127: 99.55809 | S127: =100-($R$4-R127) -> 99.48227 | T127: =($S$13-S127)/($S$13*(1-$N$1)) -> 0.011417783 | W127: 250.00297 | X127: 61.5 | Y127: 91.88328 | Z127: =100-($Y$4-Y127) -> 97.32411 | AA127: =($Z$11-Z127)/($Z$11*(1-$N$1)) -> 0.052856826 | AD127: 250.01308 | AE127: 61.5 | AF127: 98.39672 | AG127: =100-($AF$4-AF127) -> 98.65821 | AH127: =($AG$9-AG127)/($AG$9*(1-$N$1)) -> 0.031053585 | AK127: 413.47167 | AL127: 61.5 | AM127: 51.46429 | AN127: =100-($AM$4-AM127) -> 54.05051 | AO127: =($AN$8-AN127)/($AN$8*(1-$N$1)) -> 0.76742397 | AQ127: 415.95907 | AR127: 61.5 | AS127: 46.05348 | AT127: =100-($AS$4-AS127) -> 49.01221 | AU127: =($AT$7-AT127)/($AT$7*(1-$N$1)) -> 0.85094801 | AW127: 289.73827 | AX127: 61.5 | AY127: 94.86344 | AZ127: =100-($AY$4-AY127) -> 96.52909
B128: 199.95067 | C128: 62 | D128: 99.50192 | E128: =100-($D$4-D128) -> 100.62836 | F128: =($E$119-E128)/($E$119*(1-$N$1)) -> 0.001593594 | I128: 225.00907 | J128: 62 | K128: 94.96805 | L128: =100-($K$4-K128) -> 98.55512 | M128: =($L$15-L128)/($L$15*(1-$N$1)) -> 0.03258188 | P128: 225.01736 | Q128: 62 | R128: 99.52654 | S128: =100-($R$4-R128) -> 99.45072 | T128: =($S$13-S128)/($S$13*(1-$N$1)) -> 0.011943438 | W128: 250.00598 | X128: 62 | Y128: 91.85461 | Z128: =100-($Y$4-Y128) -> 97.29544 | AA128: =($Z$11-Z128)/($Z$11*(1-$N$1)) -> 0.053332882 | AD128: 250.01642 | AE128: 62 | AF128: 98.41341 | AG128: =100-($AF$4-AF128) -> 98.6749 | AH128: =($AG$9-AG128)/($AG$9*(1-$N$1)) -> 0.030776512 | AK128: 415.95918 | AL128: 62 | AM128: 50.37254 | AN128: =100-($AM$4-AM128) -> 52.95876 | AO128: =($AN$8-AN128)/($AN$8*(1-$N$1)) -> 0.78563244 | AQ128: 418.25271 | AR128: 62 | AS128: 44.85245 | AT128: =100-($AS$4-AS128) -> 47.81118 | AU128: =($AT$7-AT128)/($AT$7*(1-$N$1)) -> 0.87099148 | AW128: 291.24247 | AX128: 62 | AY128: 94.6922 | AZ128: =100-($AY$4-AY128) -> 96.35785
B129: 199.95032 | C129: 62.5 | D129: 99.316 | E129: =100-($D$4-D129) -> 100.44244 | F129: =($E$119-E129)/($E$119*(1-$N$1)) -> 0.0046740784 | I129: 225.00398 | J129: 62.5 | K129: 94.93666 | L129: =100-($K$4-K129) -> 98.52373 | M129: =($L$15-L129)/($L$15*(1-$N$1)) -> 0.033103048 | P129: 225.01805 | Q129: 62.5 | R129: 99.61713 | S129: =100-($R$4-R129) -> 99.54131 | T129: =($S$13-S129)/($S$13*(1-$N$1)) -> 0.010434118 | W129: 250.00799 | X129: 62.5 | Y129: 91.83146 | Z129: =100-($Y$4-Y129) -> 97.27229 | AA129: =($Z$11-Z129)/($Z$11*(1-$N$1)) -> 0.05371728 | AD129: 250.0172 | AE129: 62.5 | AF129: 98.32873 | AG129: =100-($AF$4-AF129) -> 98.59022 | AH129: =($AG$9-AG129)/($AG$9*(1-$N$1)) -> 0.032182296 | AK129: 418.29701 | AL129: 62.5 | AM129: 49.22763 | AN129: =100-($AM$4-AM129) -> 51.81385 | AO129: =($AN$8-AN129)/($AN$8*(1-$N$1)) -> 0.80472754 | AQ129: 420.44807 | AR129: 62.5 | AS129: 43.85983 | AT129: =100-($AS$4-AS129) -> 46.81856 | AU129: =($AT$7-AT129)/($AT$7*(1-$N$1)) -> 0.88755689 | AW129: 292.74565 | AX129: 62.5 | AY129: 94.49599 | AZ129: =100-($AY$4-AY129) -> 96.16164
B130: 199.95868 | C130: 63 | D130: 99.45647 | E130: =100-($D$4-D130) -> 100.58291 | F130: =($E$119-E130)/($E$119*(1-$N$1)) -> 0.0023466491 | I130: 225.00005 | J130: 63 | K130: 94.90255 | L130: =100-($K$4-K130) -> 98.48962 | M130: =($L$15-L130)/($L$15*(1-$N$1)) -> 0.033669376 | P130: 225.01587 | Q130: 63 | R130: 99.37517 | S130: =100-($R$4-R130) -> 99.29935 | T130: =($S$13-S130)/($S$13*(1-$N$1)) -> 0.014465413 | W130: 250.00999 | X130: 63 | Y130: 91.81813 | Z130: =100-($Y$4-Y130) -> 97.25896 | AA130: =($Z$11-Z130)/($Z$11*(1-$N$1)) -> 0.05393862 | AD130: 250.01815 | AE130: 63 | AF130: 98.36743 | AG130: =100-($AF$4-AF130) -> 98.62892 | AH130: =($AG$9-AG130)/($AG$9*(1-$N$1)) -> 0.031539832 | AK130: 420.5184 | AL130: 63 | AM130: 48.27516 | AN130: =100-($AM$4-AM130) -> 50.86138 | AO130: =($AN$8-AN130)/($AN$8*(1-$N$1)) -> 0.82061307 | AQ130: 422.62788 | AR130: 63 | AS130: 42.97606 | AT130: =100-($AS$4-AS130) -> 45.93479 | AU130: =($AT$7-AT130)/($AT$7*(1-$N$1)) -> 0.90230575 | AW130: 294.25338 | AX130: 63 | AY130: 94.37165 | AZ130: =100-($AY$4-AY130) -> 96.0373
... B280: 199.98416 | C280: 138 | D280: 99.20077 | E280: =100-($D$4-D280) -> 100.32721 | F280: =($E$119-E280)/($E$119*(1-$N$1)) -> 0.0065833093 | I280: 225.00592 | J280: 138 | K280: 92.49183 | L280: =100-($K$4-K280) -> 96.0789 | M280: =($L$15-L280)/($L$15*(1-$N$1)) -> 0.073694543 | P280: 225.01653 | Q280: 138 | R280: 98.8288 | S280: =100-($R$4-R280) -> 98.75298 | T280: =($S$13-S280)/($S$13*(1-$N$1)) -> 0.023568484 | W280: 250.00501 | X280: 138 | Y280: 88.39151 | Z280: =100-($Y$4-Y280) -> 93.83234 | AA280: =($Z$11-Z280)/($Z$11*(1-$N$1)) -> 0.11083652 | AD280: 250.01614 | AE280: 138 | AF280: 96.23508 | AG280: =100-($AF$4-AF280) -> 96.49657 | AH280: =($AG$9-AG280)/($AG$9*(1-$N$1)) -> 0.066939263 | AK280: 795.71032 | AL280: 138 | AM280: 39.13808 | AN280: =100-($AM$4-AM280) -> 41.7243 | AO280: =($AN$8-AN280)/($AN$8*(1-$N$1)) -> 0.97300357 | AQ280: 798.23196 | AR280: 138 | AS280: 33.83388 | AT280: =100-($AS$4-AS280) -> 36.79261 | AU280: =($AT$7-AT280)/($AT$7*(1-$N$1)) -> 1.0548757 | AW280: 519.30948 | AX280: 138 | AY280: 39.65663 | AZ280: =100-($AY$4-AY280) -> 41.32228
...

Sheet All Data, WS500 20% O2
L1: Ash Fraction: | M1: =17.28/100 -> 0.1728
C3: 200C Odin | I3: 225C Sif | O3: 225C Odin | U3: 250 Sif | AA3: 250 Odin | AF3: Linear (1) | AL3: Linear (2) | AR3: Linear (Used, Real)
B5: Temp | C5: Time corrected | D5: mass% raw | E5: mass% corrected | F5: X_C | H5: Temp | I5: Time corrected | J5: mass% raw | K5: mass% corrected | L5: X_C | N5: Temp | O5: Time corrected | P5: mass% raw | Q5: mass% corrected | R5: X_C | T5: Temp | U5: Time corrected | V5: mass% raw | W5: mass% corrected | X5: X_C | Z5: Temp | AA5: Time corrected | AB5: mass% raw | AC5: mass% corrected | AD5: X_C | AF5: TEMP | AG5: TIME CORRECTED | AH5: mass% raw | AI5: mass% corrected | AJ5: X_C | AL5: TEMP | AM5: TIME CORRECTED | AN5: mass% raw | AO5: mass% corrected | AP5: X_C | AR5: TEMP | AS5: TIME | AT5: MASS% | AU5: CORRECTED
B6: 200.13754 | C6: 0 | D6: 99.2867 | E6: =100-($D$6-D6) -> 100 | H6: 225.0022 | I6: 0 | J6: 95.89242 | K6: =100-($J$6-J6) -> 100 | N6: 225.01424 | O6: 0 | P6: 99.86442 | Q6: =100-($P$6-P6) -> 100 | T6: 250.00404 | U6: 0 | V6: 95.8426 | W6: =100-($V$6-V6) -> 100 | Z6: 250.0306 | AA6: 0 | AB6: 100.07674 | AC6: =100-($AB$6-AB6) -> 100 | AF6: 105.24614 | AG6: 0 | AH6: 96.99231 | AI6: =100-($AH$6-AH6) -> 100 | AL6: 105.24296 | AM6: 0 | AN6: 96.9065 | AO6: =100-($AN$6-AN6) -> 100 | AR6: 88.56245 | AS6: 0 | AT6: 99.34551 | AU6: =100-($AT$6-AT6) -> 100
B7: 202.32401 | C7: 0.5 | D7: 99.31842 | E7: =100-($D$6-D7) -> 100.03172 | H7: 225.19024 | I7: 0.5 | J7: 95.967 | K7: =100-($J$6-J7) -> 100.07458 | N7: 227.13638 | O7: 0.5 | P7: 99.88271 | Q7: =100-($P$6-P7) -> 100.01829 | T7: 250.3317 | U7: 0.5 | V7: 95.97793 | W7: =100-($V$6-V7) -> 100.13533 | Z7: 250.10088 | AA7: 0.5 | AB7: 100.2651 | AC7: =100-($AB$6-AB7) -> 100.18836 | AF7: 106.53965 | AG7: 0.5 | AH7: 97.01694 | AI7: =100-($AH$6-AH7) -> 100.02463 | AJ7: =($AI$7-AI7)/($AI$7*(1-$M$1)) -> 0 | AL7: 106.52568 | AM7: 0.5 | AN7: 96.96309 | AO7: =100-($AN$6-AN7) -> 100.05659 | AR7: 91.03717 | AS7: 0.5 | AT7: 99.35674 | AU7: =100-($AT$6-AT7) -> 100.01123
B8: 204.02187 | C8: 1 | D8: 99.32854 | E8: =100-($D$6-D8) -> 100.04184 | H8: 225.29404 | I8: 1 | J8: 96.08491 | K8: =100-($J$6-J8) -> 100.19249 | N8: 228.74259 | O8: 1 | P8: 100.04307 | Q8: =100-($P$6-P8) -> 100.17865 | T8: 250.50292 | U8: 1 | V8: 96.13007 | W8: =100-($V$6-V8) -> 100.28747 | Z8: 250.20709 | AA8: 1 | AB8: 100.48717 | AC8: =100-($AB$6-AB8) -> 100.41043 | AF8: 108.3906 | AG8: 1 | AH8: 96.9899 | AI8: =100-($AH$6-AH8) -> 99.99759 | AJ8: =($AI$7-AI8)/($AI$7*(1-$M$1)) -> 0.00032680539 | AL8: 108.3897 | AM8: 1 | AN8: 96.9778 | AO8: =100-($AN$6-AN8) -> 100.0713 | AR8: 94.69499 | AS8: 1 | AT8: 99.3449 | AU8: =100-($AT$6-AT8) -> 99.99939
B9: 205.1072 | C9: 1.5 | D9: 99.48585 | E9: =100-($D$6-D9) -> 100.19915 | H9: 225.2497 | I9: 1.5 | J9: 96.12092 | K9: =100-($J$6-J9) -> 100.2285 | N9: 229.70961 | O9: 1.5 | P9: 100.01632 | Q9: =100-($P$6-P9) -> 100.1519 | T9: 250.40885 | U9: 1.5 | V9: 96.21449 | W9: =100-($V$6-V9) -> 100.37189 | Z9: 250.23091 | AA9: 1.5 | AB9: 100.63858 | AC9: =100-($AB$6-AB9) -> 100.56184 | AF9: 110.66411 | AG9: 1.5 | AH9: 97.00504 | AI9: =100-($AH$6-AH9) -> 100.01273 | AJ9: =($AI$7-AI9)/($AI$7*(1-$M$1)) -> 0.00014382338 | AL9: 110.66279 | AM9: 1.5 | AN9: 96.97674 | AO9: =100-($AN$6-AN9) -> 100.07024 | AR9: 98.78422 | AS9: 1.5 | AT9: 99.33503 | AU9: =100-($AT$6-AT9) -> 99.98952
B10: 205.68174 | C10: 2 | D10: 99.38137 | E10: =100-($D$6-D10) -> 100.09467 | H10: 225.1747 | I10: 2 | J10: 96.17595 | K10: =100-($J$6-J10) -> 100.28353 | N10: 230.15885 | O10: 2 | P10: 100.07545 | Q10: =100-($P$6-P10) -> 100.21103 | T10: 250.26179 | U10: 2 | V10: 96.26242 | W10: =100-($V$6-V10) -> 100.41982 | Z10: 250.19853 | AA10: 2 | AB10: 100.62768 | AC10: =100-($AB$6-AB10) -> 100.55094 | AF10: 113.18211 | AG10: 2 | AH10: 96.98857 | AI10: =100-($AH$6-AH10) -> 99.99626 | AJ10: =($AI$7-AI10)/($AI$7*(1-$M$1)) -> 0.00034287977 | AL10: 113.19429 | AM10: 2 | AN10: 96.99134 | AO10: =100-($AN$6-AN10) -> 100.08484 | AP10: =($AO$10-AO10)/($AO$10*(1-$M$1)) -> 0 | AR10: 102.84047 | AS10: 2 | AT10: 99.3251 | AU10: =100-($AT$6-AT10) -> 99.97959
B11: 205.92954 | C11: 2.5 | D11: 99.40736 | E11: =100-($D$6-D11) -> 100.12066 | H11: 225.10865 | I11: 2.5 | J11: 96.19419 | K11: =100-($J$6-J11) -> 100.30177 | N11: 230.31051 | O11: 2.5 | P11: 100.15618 | Q11: =100-($P$6-P11) -> 100.29176 | T11: 250.14185 | U11: 2.5 | V11: 96.30456 | W11: =100-($V$6-V11) -> 100.46196 | Z11: 250.15042 | AA11: 2.5 | AB11: 100.78744 | AC11: =100-($AB$6-AB11) -> 100.7107 | AF11: 115.86236 | AG11: 2.5 | AH11: 96.9993 | AI11: =100-($AH$6-AH11) -> 100.00699 | AJ11: =($AI$7-AI11)/($AI$7*(1-$M$1)) -> 0.00021319701 | AL11: 115.86379 | AM11: 2.5 | AN11: 96.95929 | AO11: =100-($AN$6-AN11) -> 100.05279 | AP11: =($AO$10-AO11)/($AO$10*(1-$M$1)) -> 0.00038712321 | AR11: 106.59145 | AS11: 2.5 | AT11: 99.35008 | AU11: =100-($AT$6-AT11) -> 100.00457
B12: 205.99668 | C12: 3 | D12: 99.52164 | E12: =100-($D$6-D12) -> 100.23494 | H12: 225.0498 | I12: 3 | J12: 96.19421 | K12: =100-($J$6-J12) -> 100.30179 | N12: 230.32631 | O12: 3 | P12: 100.24469 | Q12: =100-($P$6-P12) -> 100.38027 | T12: 250.05887 | U12: 3 | V12: 96.35068 | W12: =100-($V$6-V12) -> 100.50808 | Z12: 250.11347 | AA12: 3 | AB12: 100.6946 | AC12: =100-($AB$6-AB12) -> 100.61786 | AF12: 118.60193 | AG12: 3 | AH12: 96.96458 | AI12: =100-($AH$6-AH12) -> 99.97227 | AJ12: =($AI$7-AI12)/($AI$7*(1-$M$1)) -> 0.00063282286 | AL12: 118.61694 | AM12: 3 | AN12: 96.93421 | AO12: =100-($AN$6-AN12) -> 100.02771 | AP12: =($AO$10-AO12)/($AO$10*(1-$M$1)) -> 0.00069005769 | AR12: 109.94798 | AS12: 3 | AT12: 99.33544 | AU12: =100-($AT$6-AT12) -> 99.98993
B13: 205.97029 | C13: 3.5 | D13: 99.5658 | E13: =100-($D$6-D13) -> 100.2791 | H13: 225.01489 | I13: 3.5 | J13: 96.23912 | K13: =100-($J$6-J13) -> 100.3467 | N13: 230.2874 | O13: 3.5 | P13: 100.23308 | Q13: =100-($P$6-P13) -> 100.36866 | T13: 249.99692 | U13: 3.5 | V13: 96.37281 | W13: =100-($V$6-V13) -> 100.53021 | Z13: 250.08651 | AA13: 3.5 | AB13: 100.85159 | AC13: =100-($AB$6-AB13) -> 100.77485 | AF13: 121.36984 | AG13: 3.5 | AH13: 96.94174 | AI13: =100-($AH$6-AH13) -> 99.94943 | AJ13: =($AI$7-AI13)/($AI$7*(1-$M$1)) -> 0.00090886706 | AL13: 121.38763 | AM13: 3.5 | AN13: 96.93166 | AO13: =100-($AN$6-AN13) -> 100.02516 | AP13: =($AO$10-AO13)/($AO$10*(1-$M$1)) -> 0.00072085844 | AR13: 112.88425 | AS13: 3.5 | AT13: 99.31143 | AU13: =100-($AT$6-AT13) -> 99.96592
B14: 205.87992 | C14: 4 | D14: 99.52699 | E14: =100-($D$6-D14) -> 100.24029 | H14: 224.9908 | I14: 4 | J14: 96.25166 | K14: =100-($J$6-J14) -> 100.35924 | N14: 230.20675 | O14: 4 | P14: 100.22795 | Q14: =100-($P$6-P14) -> 100.36353 | T14: 249.95792 | U14: 4 | V14: 96.38665 | W14: =100-($V$6-V14) -> 100.54405 | Z14: 250.0679 | AA14: 4 | AB14: 100.84871 | AC14: =100-($AB$6-AB14) -> 100.77197 | AF14: 124.13326 | AG14: 4 | AH14: 96.92538 | AI14: =100-($AH$6-AH14) -> 99.93307 | AJ14: =($AI$7-AI14)/($AI$7*(1-$M$1)) -> 0.001106594 | AL14: 124.1364 | AM14: 4 | AN14: 96.89289 | AO14: =100-($AN$6-AN14) -> 99.98639 | AP14: =($AO$10-AO14)/($AO$10*(1-$M$1)) -> 0.0011891507 | AR14: 115.42524 | AS14: 4 | AT14: 99.31795 | AU14: =100-($AT$6-AT14) -> 99.97244
B15: 205.72739 | C15: 4.5 | D15: 99.49221 | E15: =100-($D$6-D15) -> 100.20551 | H15: 224.97685 | I15: 4.5 | J15: 96.24643 | K15: =100-($J$6-J15) -> 100.35401 | N15: 230.06839 | O15: 4.5 | P15: 100.39991 | Q15: =100-($P$6-P15) -> 100.53549 | T15: 249.94597 | U15: 4.5 | V15: 96.40255 | W15: =100-($V$6-V15) -> 100.55995 | Z15: 250.05477 | AA15: 4.5 | AB15: 100.79655 | AC15: =100-($AB$6-AB15) -> 100.71981 | AF15: 126.84022 | AG15: 4.5 | AH15: 96.91502 | AI15: =100-($AH$6-AH15) -> 99.92271 | AJ15: =($AI$7-AI15)/($AI$7*(1-$M$1)) -> 0.0012318049 | AL15: 126.84249 | AM15: 4.5 | AN15: 96.87774 | AO15: =100-($AN$6-AN15) -> 99.97124 | AP15: =($AO$10-AO15)/($AO$10*(1-$M$1)) -> 0.0013721434 | AR15: 117.64344 | AS15: 4.5 | AT15: 99.3062 | AU15: =100-($AT$6-AT15) -> 99.96069
B16: 205.50274 | C16: 5 | D16: 99.55578 | E16: =100-($D$6-D16) -> 100.26908 | H16: 224.96697 | I16: 5 | J16: 96.25544 | K16: =100-($J$6-J16) -> 100.36302 | N16: 229.85206 | O16: 5 | P16: 100.21492 | Q16: =100-($P$6-P16) -> 100.3505 | T16: 249.94298 | U16: 5 | V16: 96.42681 | W16: =100-($V$6-V16) -> 100.58421 | Z16: 250.04676 | AA16: 5 | AB16: 100.89208 | AC16: =100-($AB$6-AB16) -> 100.81534 | AF16: 129.50186 | AG16: 5 | AH16: 96.87951 | AI16: =100-($AH$6-AH16) -> 99.8872 | AJ16: =($AI$7-AI16)/($AI$7*(1-$M$1)) -> 0.0016609787 | AL16: 129.49874 | AM16: 5 | AN16: 96.85992 | AO16: =100-($AN$6-AN16) -> 99.95342 | AP16: =($AO$10-AO16)/($AO$10*(1-$M$1)) -> 0.0015873863 | AR16: 119.60632 | AS16: 5 | AT16: 99.30908 | AU16: =100-($AT$6-AT16) -> 99.96357
B17: 205.20155 | C17: 5.5 | D17: 99.59917 | E17: =100-($D$6-D17) -> 100.31247 | H17: 224.968 | I17: 5.5 | J17: 96.28191 | K17: =100-($J$6-J17) -> 100.38949 | N17: 229.57033 | O17: 5.5 | P17: 100.21313 | Q17: =100-($P$6-P17) -> 100.34871 | T17: 249.94199 | U17: 5.5 | V17: 96.43915 | W17: =100-($V$6-V17) -> 100.59655 | Z17: 250.03738 | AA17: 5.5 | AB17: 100.87633 | AC17: =100-($AB$6-AB17) -> 100.79959 | AF17: 132.14314 | AG17: 5.5 | AH17: 96.86395 | AI17: =100-($AH$6-AH17) -> 99.87164 | AJ17: =($AI$7-AI17)/($AI$7*(1-$M$1)) -> 0.0018490368 | AL17: 132.14378 | AM17: 5.5 | AN17: 96.84965 | AO17: =100-($AN$6-AN17) -> 99.94315 | AP17: =($AO$10-AO17)/($AO$10*(1-$M$1)) -> 0.0017114349 | AR17: 121.38794 | AS17: 5.5 | AT17: 99.28993 | AU17: =100-($AT$6-AT17) -> 99.94442
B18: 204.84555 | C18: 6 | D18: 99.48091 | E18: =100-($D$6-D18) -> 100.19421 | H18: 224.97083 | I18: 6 | J18: 96.2663 | K18: =100-($J$6-J18) -> 100.37388 | N18: 229.23922 | O18: 6 | P18: 100.36311 | Q18: =100-($P$6-P18) -> 100.49869 | T18: 249.95198 | U18: 6 | V18: 96.44501 | W18: =100-($V$6-V18) -> 100.60241 | Z18: 250.02669 | AA18: 6 | AB18: 100.7816 | AC18: =100-($AB$6-AB18) -> 100.70486 | AF18: 134.76502 | AG18: 6 | AH18: 96.83666 | AI18: =100-($AH$6-AH18) -> 99.84435 | AJ18: =($AI$7-AI18)/($AI$7*(1-$M$1)) -> 0.0021788637 | AL18: 134.76534 | AM18: 6 | AN18: 96.81293 | AO18: =100-($AN$6-AN18) -> 99.90643 | AP18: =($AO$10-AO18)/($AO$10*(1-$M$1)) -> 0.0021549657 | AR18: 123.04157 | AS18: 6 | AT18: 99.29192 | AU18: =100-($AT$6-AT18) -> 99.94641
B19: 204.45732 | C19: 6.5 | D19: 99.57294 | E19: =100-($D$6-D19) -> 100.28624 | H19: 224.97686 | I19: 6.5 | J19: 96.25283 | K19: =100-($J$6-J19) -> 100.36041 | N19: 228.87646 | O19: 6.5 | P19: 100.22019 | Q19: =100-($P$6-P19) -> 100.35577 | T19: 249.954 | U19: 6.5 | V19: 96.45092 | W19: =100-($V$6-V19) -> 100.60832 | Z19: 250.01678 | AA19: 6.5 | AB19: 100.90948 | AC19: =100-($AB$6-AB19) -> 100.83274 | AF19: 137.35039 | AG19: 6.5 | AH19: 96.79717 | AI19: =100-($AH$6-AH19) -> 99.80486 | AJ19: =($AI$7-AI19)/($AI$7*(1-$M$1)) -> 0.0026561398 | AL19: 137.34816 | AM19: 6.5 | AN19: 96.76816 | AO19: =100-($AN$6-AN19) -> 99.86166 | AP19: =($AO$10-AO19)/($AO$10*(1-$M$1)) -> 0.0026957304 | AR19: 124.59525 | AS19: 6.5 | AT19: 99.26671 | AU19: =100-($AT$6-AT19) -> 99.9212
B20: 204.04987 | C20: 7 | D20: 99.51127 | E20: =100-($D$6-D20) -> 100.22457 | H20: 224.97709 | I20: 7 | J20: 96.28792 | K20: =100-($J$6-J20) -> 100.3955 | L20: =($K$20-K20)/($K$20*(1-$M$1)) -> 0 | N20: 228.5092 | O20: 7 | P20: 100.32958 | Q20: =100-($P$6-P20) -> 100.46516 | T20: 249.959 | U20: 7 | V20: 96.46901 | W20: =100-($V$6-V20) -> 100.62641 | Z20: 250.00823 | AA20: 7 | AB20: 100.81736 | AC20: =100-($AB$6-AB20) -> 100.74062 | AF20: 139.89643 | AG20: 7 | AH20: 96.78861 | AI20: =100-($AH$6-AH20) -> 99.7963 | AJ20: =($AI$7-AI20)/($AI$7*(1-$M$1)) -> 0.0027595959 | AL20: 139.89721 | AM20: 7 | AN20: 96.7563 | AO20: =100-($AN$6-AN20) -> 99.8498 | AP20: =($AO$10-AO20)/($AO$10*(1-$M$1)) -> 0.0028389841 | AR20: 126.11534 | AS20: 7 | AT20: 99.25506 | AU20: =100-($AT$6-AT20) -> 99.90955
B21: 203.64996 | C21: 7.5 | D21: 99.62078 | E21: =100-($D$6-D21) -> 100.33408 | H21: 224.98104 | I21: 7.5 | J21: 96.27674 | K21: =100-($J$6-J21) -> 100.38432 | L21: =($K$20-K21)/($K$20*(1-$M$1)) -> 0.00013462231 | N21: 228.15946 | O21: 7.5 | P21: 100.4316 | Q21: =100-($P$6-P21) -> 100.56718 | T21: 249.961 | U21: 7.5 | V21: 96.47508 | W21: =100-($V$6-V21) -> 100.63248 | X21: =($W$21-W21)/($W$21*(1-$M$1)) -> 0 | Z21: 249.99992 | AA21: 7.5 | AB21: 100.93646 | AC21: =100-($AB$6-AB21) -> 100.85972 | AF21: 142.44809 | AG21: 7.5 | AH21: 96.74663 | AI21: =100-($AH$6-AH21) -> 99.75432 | AJ21: =($AI$7-AI21)/($AI$7*(1-$M$1)) -> 0.0032669661 | AL21: 142.45516 | AM21: 7.5 | AN21: 96.75773 | AO21: =100-($AN$6-AN21) -> 99.85123 | AP21: =($AO$10-AO21)/($AO$10*(1-$M$1)) -> 0.0028217115 | AR21: 127.59842 | AS21: 7.5 | AT21: 99.28084 | AU21: =100-($AT$6-AT21) -> 99.93533
B22: 203.2737 | C22: 8 | D22: 99.62749 | E22: =100-($D$6-D22) -> 100.34079 | H22: 224.98303 | I22: 8 | J22: 96.27496 | K22: =100-($J$6-J22) -> 100.38254 | L22: =($K$20-K22)/($K$20*(1-$M$1)) -> 0.00015605591 | N22: 227.83213 | O22: 8 | P22: 100.3665 | Q22: =100-($P$6-P22) -> 100.50208 | T22: 249.97202 | U22: 8 | V22: 96.46475 | W22: =100-($V$6-V22) -> 100.62215 | X22: =($W$21-W22)/($W$21*(1-$M$1)) -> 0.00012409424 | Z22: 249.99879 | AA22: 8 | AB22: 100.89754 | AC22: =100-($AB$6-AB22) -> 100.8208 | AF22: 145.01178 | AG22: 8 | AH22: 96.73217 | AI22: =100-($AH$6-AH22) -> 99.73986 | AJ22: =($AI$7-AI22)/($AI$7*(1-$M$1)) -> 0.0034417297 | AL22: 145.01205 | AM22: 8 | AN22: 96.71525 | AO22: =100-($AN$6-AN22) -> 99.80875 | AP22: =($AO$10-AO22)/($AO$10*(1-$M$1)) -> 0.0033348158 | AR22: 129.07237 | AS22: 8 | AT22: 99.27558 | AU22: =100-($AT$6-AT22) -> 99.93007
B23: 202.9223 | C23: 8.5 | D23: 99.62425 | E23: =100-($D$6-D23) -> 100.33755 | H23: 224.98508 | I23: 8.5 | J23: 96.26048 | K23: =100-($J$6-J23) -> 100.36806 | L23: =($K$20-K23)/($K$20*(1-$M$1)) -> 0.00033041468 | N23: 227.53049 | O23: 8.5 | P23: 100.29575 | Q23: =100-($P$6-P23) -> 100.43133 | T23: 249.97604 | U23: 8.5 | V23: 96.44696 | W23: =100-($V$6-V23) -> 100.60436 | X23: =($W$21-W23)/($W$21*(1-$M$1)) -> 0.00033780542 | Z23: 249.99602 | AA23: 8.5 | AB23: 100.89047 | AC23: =100-($AB$6-AB23) -> 100.81373 | AF23: 147.53725 | AG23: 8.5 | AH23: 96.71772 | AI23: =100-($AH$6-AH23) -> 99.72541 | AJ23: =($AI$7-AI23)/($AI$7*(1-$M$1)) -> 0.0036163723 | AL23: 147.51711 | AM23: 8.5 | AN23: 96.69542 | AO23: =100-($AN$6-AN23) -> 99.78892 | AP23: =($AO$10-AO23)/($AO$10*(1-$M$1)) -> 0.003574337 | AR23: 130.52289 | AS23: 8.5 | AT23: 99.26275 | AU23: =100-($AT$6-AT23) -> 99.91724
B24: 202.59182 | C24: 9 | D24: 99.61363 | E24: =100-($D$6-D24) -> 100.32693 | H24: 224.98995 | I24: 9 | J24: 96.25803 | K24: =100-($J$6-J24) -> 100.36561 | L24: =($K$20-K24)/($K$20*(1-$M$1)) -> 0.00035991599 | N24: 227.24494 | O24: 9 | P24: 100.32734 | Q24: =100-($P$6-P24) -> 100.46292 | T24: 249.97503 | U24: 9 | V24: 96.47302 | W24: =100-($V$6-V24) -> 100.63042 | X24: =($W$21-W24)/($W$21*(1-$M$1)) -> 2.474677e-05 | Z24: 249.99668 | AA24: 9 | AB24: 100.87937 | AC24: =100-($AB$6-AB24) -> 100.80263 | AF24: 150.05991 | AG24: 9 | AH24: 96.70847 | AI24: =100-($AH$6-AH24) -> 99.71616 | AJ24: =($AI$7-AI24)/($AI$7*(1-$M$1)) -> 0.0037281678 | AL24: 150.05204 | AM24: 9 | AN24: 96.69248 | AO24: =100-($AN$6-AN24) -> 99.78598 | AP24: =($AO$10-AO24)/($AO$10*(1-$M$1)) -> 0.0036098484 | AR24: 131.98257 | AS24: 9 | AT24: 99.28824 | AU24: =100-($AT$6-AT24) -> 99.94273
B25: 202.28306 | C25: 9.5 | D25: 99.62432 | E25: =100-($D$6-D25) -> 100.33762 | H25: 224.99402 | I25: 9.5 | J25: 96.24502 | K25: =100-($J$6-J25) -> 100.3526 | L25: =($K$20-K25)/($K$20*(1-$M$1)) -> 0.00051657397 | N25: 226.9856 | O25: 9.5 | P25: 100.28356 | Q25: =100-($P$6-P25) -> 100.41914 | T25: 249.97391 | U25: 9.5 | V25: 96.47501 | W25: =100-($V$6-V25) -> 100.63241 | X25: =($W$21-W25)/($W$21*(1-$M$1)) -> 8.4090965e-07 | Z25: 249.99771 | AA25: 9.5 | AB25: 100.91562 | AC25: =100-($AB$6-AB25) -> 100.83888 | AF25: 152.60746 | AG25: 9.5 | AH25: 96.67878 | AI25: =100-($AH$6-AH25) -> 99.68647 | AJ25: =($AI$7-AI25)/($AI$7*(1-$M$1)) -> 0.0040870011 | AL25: 152.61124 | AM25: 9.5 | AN25: 96.65308 | AO25: =100-($AN$6-AN25) -> 99.74658 | AP25: =($AO$10-AO25)/($AO$10*(1-$M$1)) -> 0.0040857503 | AR25: 133.45019 | AS25: 9.5 | AT25: 99.25261 | AU25: =100-($AT$6-AT25) -> 99.9071
B26: 201.99963 | C26: 10 | D26: 99.61851 | E26: =100-($D$6-D26) -> 100.33181 | H26: 224.9921 | I26: 10 | J26: 96.24082 | K26: =100-($J$6-J26) -> 100.3484 | L26: =($K$20-K26)/($K$20*(1-$M$1)) -> 0.00056714765 | N26: 226.74379 | O26: 10 | P26: 100.49606 | Q26: =100-($P$6-P26) -> 100.63164 | T26: 249.98199 | U26: 10 | V26: 96.43495 | W26: =100-($V$6-V26) -> 100.59235 | X26: =($W$21-W26)/($W$21*(1-$M$1)) -> 0.00048208149 | Z26: 249.99483 | AA26: 10 | AB26: 100.96595 | AC26: =100-($AB$6-AB26) -> 100.88921 | AF26: 155.13622 | AG26: 10 | AH26: 96.66987 | AI26: =100-($AH$6-AH26) -> 99.67756 | AJ26: =($AI$7-AI26)/($AI$7*(1-$M$1)) -> 0.0041946874 | AL26: 155.11712 | AM26: 10 | AN26: 96.65278 | AO26: =100-($AN$6-AN26) -> 99.74628 | AP26: =($AO$10-AO26)/($AO$10*(1-$M$1)) -> 0.0040893739 | AR26: 134.94415 | AS26: 10 | AT26: 99.2535 | AU26: =100-($AT$6-AT26) -> 99.90799
B27: 201.74115 | C27: 10.5 | D27: 99.68937 | E27: =100-($D$6-D27) -> 100.40267 | H27: 224.99204 | I27: 10.5 | J27: 96.24073 | K27: =100-($J$6-J27) -> 100.34831 | L27: =($K$20-K27)/($K$20*(1-$M$1)) -> 0.00056823137 | N27: 226.5186 | O27: 10.5 | P27: 100.40046 | Q27: =100-($P$6-P27) -> 100.53604 | T27: 249.97601 | U27: 10.5 | V27: 96.45291 | W27: =100-($V$6-V27) -> 100.61031 | X27: =($W$21-W27)/($W$21*(1-$M$1)) -> 0.0002663281 | Z27: 249.9927 | AA27: 10.5 | AB27: 100.90623 | AC27: =100-($AB$6-AB27) -> 100.82949 | AF27: 157.6449 | AG27: 10.5 | AH27: 96.6209 | AI27: =100-($AH$6-AH27) -> 99.62859 | AJ27: =($AI$7-AI27)/($AI$7*(1-$M$1)) -> 0.0047865387 | AL27: 157.64431 | AM27: 10.5 | AN27: 96.59153 | AO27: =100-($AN$6-AN27) -> 99.68503 | AP27: =($AO$10-AO27)/($AO$10*(1-$M$1)) -> 0.0048291959 | AR27: 136.44254 | AS27: 10.5 | AT27: 99.2335 | AU27: =100-($AT$6-AT27) -> 99.88799
B28: 201.50387 | C28: 11 | D28: 99.5504 | E28: =100-($D$6-D28) -> 100.2637 | H28: 224.99203 | I28: 11 | J28: 96.22842 | K28: =100-($J$6-J28) -> 100.336 | L28: =($K$20-K28)/($K$20*(1-$M$1)) -> 0.0007164604 | N28: 226.31841 | O28: 11 | P28: 100.31781 | Q28: =100-($P$6-P28) -> 100.45339 | T28: 249.98201 | U28: 11 | V28: 96.45305 | W28: =100-($V$6-V28) -> 100.61045 | X28: =($W$21-W28)/($W$21*(1-$M$1)) -> 0.00026464628 | Z28: 249.99523 | AA28: 11 | AB28: 100.9675 | AC28: =100-($AB$6-AB28) -> 100.89076 | AF28: 160.19764 | AG28: 11 | AH28: 96.63312 | AI28: =100-($AH$6-AH28) -> 99.64081 | AJ28: =($AI$7-AI28)/($AI$7*(1-$M$1)) -> 0.0046388478 | AL28: 160.19083 | AM28: 11 | AN28: 96.62122 | AO28: =100-($AN$6-AN28) -> 99.71472 | AP28: =($AO$10-AO28)/($AO$10*(1-$M$1)) -> 0.0044705785 | AR28: 137.93097 | AS28: 11 | AT28: 99.24083 | AU28: =100-($AT$6-AT28) -> 99.89532
B29: 201.2875 | C29: 11.5 | D29: 99.73074 | E29: =100-($D$6-D29) -> 100.44404 | H29: 224.99396 | I29: 11.5 | J29: 96.24904 | K29: =100-($J$6-J29) -> 100.35662 | L29: =($K$20-K29)/($K$20*(1-$M$1)) -> 0.00046816774 | N29: 226.13982 | O29: 11.5 | P29: 100.54063 | Q29: =100-($P$6-P29) -> 100.67621 | T29: 249.98399 | U29: 11.5 | V29: 96.43273 | W29: =100-($V$6-V29) -> 100.59013 | X29: =($W$21-W29)/($W$21*(1-$M$1)) -> 0.00050875034 | Z29: 249.99524 | AA29: 11.5 | AB29: 101.01947 | AC29: =100-($AB$6-AB29) -> 100.94273 | AF29: 162.70512 | AG29: 11.5 | AH29: 96.5915 | AI29: =100-($AH$6-AH29) -> 99.59919 | AJ29: =($AI$7-AI29)/($AI$7*(1-$M$1)) -> 0.005141867 | AL29: 162.69316 | AM29: 11.5 | AN29: 96.56872 | AO29: =100-($AN$6-AN29) -> 99.66222 | AP29: =($AO$10-AO29)/($AO$10*(1-$M$1)) -> 0.0051047117 | AR29: 139.4219 | AS29: 11.5 | AT29: 99.23793 | AU29: =100-($AT$6-AT29) -> 99.89242
B30: 201.09436 | C30: 12 | D30: 99.46951 | E30: =100-($D$6-D30) -> 100.18281 | H30: 224.99201 | I30: 12 | J30: 96.22626 | K30: =100-($J$6-J30) -> 100.33384 | L30: =($K$20-K30)/($K$20*(1-$M$1)) -> 0.00074246972 | N30: 225.98372 | O30: 12 | P30: 100.49329 | Q30: =100-($P$6-P30) -> 100.62887 | T30: 249.98898 | U30: 12 | V30: 96.4247 | W30: =100-($V$6-V30) -> 100.5821 | X30: =($W$21-W30)/($W$21*(1-$M$1)) -> 0.00060521469 | Z30: 249.99323 | AA30: 12 | AB30: 101.02344 | AC30: =100-($AB$6-AB30) -> 100.9467 | AF30: 165.20859 | AG30: 12 | AH30: 96.57954 | AI30: =100-($AH$6-AH30) -> 99.58723 | AJ30: =($AI$7-AI30)/($AI$7*(1-$M$1)) -> 0.0052864156 | AL30: 165.21582 | AM30: 12 | AN30: 96.58555 | AO30: =100-($AN$6-AN30) -> 99.67905 | AP30: =($AO$10-AO30)/($AO$10*(1-$M$1)) -> 0.0049014267 | AR30: 140.92148 | AS30: 12 | AT30: 99.22888 | AU30: =100-($AT$6-AT30) -> 99.88337
B31: 200.92884 | C31: 12.5 | D31: 99.58507 | E31: =100-($D$6-D31) -> 100.29837 | H31: 224.99487 | I31: 12.5 | J31: 96.2369 | K31: =100-($J$6-J31) -> 100.34448 | L31: =($K$20-K31)/($K$20*(1-$M$1)) -> 0.00061434974 | N31: 225.84763 | O31: 12.5 | P31: 100.36519 | Q31: =100-($P$6-P31) -> 100.50077 | T31: 249.989 | U31: 12.5 | V31: 96.43291 | W31: =100-($V$6-V31) -> 100.59031 | X31: =($W$21-W31)/($W$21*(1-$M$1)) -> 0.000506588 | Z31: 249.98999 | AA31: 12.5 | AB31: 100.97095 | AC31: =100-($AB$6-AB31) -> 100.89421 | AF31: 167.72856 | AG31: 12.5 | AH31: 96.56514 | AI31: =100-($AH$6-AH31) -> 99.57283 | AJ31: =($AI$7-AI31)/($AI$7*(1-$M$1)) -> 0.0054604539 | AL31: 167.72123 | AM31: 12.5 | AN31: 96.54708 | AO31: =100-($AN$6-AN31) -> 99.64058 | AP31: =($AO$10-AO31)/($AO$10*(1-$M$1)) -> 0.0053660954 | AR31: 142.44892 | AS31: 12.5 | AT31: 99.24446 | AU31: =100-($AT$6-AT31) -> 99.89895
