Workbook

Sheet All Data
C3: 200C Odin | I3: 225C Sif | O3: 225C Odin | U3: 250 Sif | AA3: 250 Odin
B5: Temp | C5: Time corrected | D5: mass% raw | E5: mass% corrected | F5: X_C | H5: Temp | I5: Time corrected | J5: mass% raw | K5: mass% corrected | L5: X_C | N5: Temp | O5: Time corrected | P5: mass% raw | Q5: mass% corrected | R5: X_C | T5: Temp | U5: Time corrected | V5: mass% raw | W5: mass% corrected | X5: X_C | Z5: Temp | AA5: Time corrected | AB5: mass% raw | AC5: mass% corrected | AD5: X_C
B6: 200.13754 | C6: 0 | D6: 99.2867 | E6: =100-($D$6-D6) -> 100 | H6: 225.0022 | I6: 0 | J6: 95.89242 | K6: =100-($J$6-J6) -> 100 | N6: 225.01424 | O6: 0 | P6: 99.86442 | Q6: =100-($P$6-P6) -> 100 | T6: 250.00404 | U6: 0 | V6: 95.8426 | W6: =100-($V$6-V6) -> 100 | Z6: 250.0306 | AA6: 0 | AB6: 100.07674 | AC6: =100-($AB$6-AB6) -> 100
B7: 202.32401 | C7: 0.5 | D7: 99.31842 | E7: =100-($D$6-D7) -> 100.03172 | H7: 225.19024 | I7: 0.5 | J7: 95.967 | K7: =100-($J$6-J7) -> 100.07458 | N7: 227.13638 | O7: 0.5 | P7: 99.88271 | Q7: =100-($P$6-P7) -> 100.01829 | T7: 250.3317 | U7: 0.5 | V7: 95.97793 | W7: =100-($V$6-V7) -> 100.13533 | Z7: 250.10088 | AA7: 0.5 | AB7: 100.2651 | AC7: =100-($AB$6-AB7) -> 100.18836
B8: 204.02187 | C8: 1 | D8: 99.32854 | E8: =100-($D$6-D8) -> 100.04184 | H8: 225.29404 | I8: 1 | J8: 96.08491 | K8: =100-($J$6-J8) -> 100.19249 | N8: 228.74259 | O8: 1 | P8: 100.04307 | Q8: =100-($P$6-P8) -> 100.17865 | T8: 250.50292 | U8: 1 | V8: 96.13007 | W8: =100-($V$6-V8) -> 100.28747 | Z8: 250.20709 | AA8: 1 | AB8: 100.48717 | AC8: =100-($AB$6-AB8) -> 100.41043
B9: 205.1072 | C9: 1.5 | D9: 99.48585 | E9: =100-($D$6-D9) -> 100.19915 | H9: 225.2497 | I9: 1.5 | J9: 96.12092 | K9: =100-($J$6-J9) -> 100.2285 | N9: 229.70961 | O9: 1.5 | P9: 100.01632 | Q9: =100-($P$6-P9) -> 100.1519 | T9: 250.40885 | U9: 1.5 | V9: 96.21449 | W9: =100-($V$6-V9) -> 100.37189 | Z9: 250.23091 | AA9: 1.5 | AB9: 100.63858 | AC9: =100-($AB$6-AB9) -> 100.56184
B10: 205.68174 | C10: 2 | D10: 99.38137 | E10: =100-($D$6-D10) -> 100.09467 | H10: 225.1747 | I10: 2 | J10: 96.17595 | K10: =100-($J$6-J10) -> 100.28353 | N10: 230.15885 | O10: 2 | P10: 100.07545 | Q10: =100-($P$6-P10) -> 100.21103 | T10: 250.26179 | U10: 2 | V10: 96.26242 | W10: =100-($V$6-V10) -> 100.41982 | Z10: 250.19853 | AA10: 2 | AB10: 100.62768 | AC10: =100-($AB$6-AB10) -> 100.55094
B11: 205.92954 | C11: 2.5 | D11: 99.40736 | E11: =100-($D$6-D11) -> 100.12066 | H11: 225.10865 | I11: 2.5 | J11: 96.19419 | K11: =100-($J$6-J11) -> 100.30177 | N11: 230.31051 | O11: 2.5 | P11: 100.15618 | Q11: =100-($P$6-P11) -> 100.29176 | T11: 250.14185 | U11: 2.5 | V11: 96.30456 | W11: =100-($V$6-V11) -> 100.46196 | Z11: 250.15042 | AA11: 2.5 | AB11: 100.78744 | AC11: =100-($AB$6-AB11) -> 100.7107
B12: 205.99668 | C12: 3 | D12: 99.52164 | E12: =100-($D$6-D12) -> 100.23494 | H12: 225.0498 | I12: 3 | J12: 96.19421 | K12: =100-($J$6-J12) -> 100.30179 | N12: 230.32631 | O12: 3 | P12: 100.24469 | Q12: =100-($P$6-P12) -> 100.38027 | T12: 250.05887 | U12: 3 | V12: 96.35068 | W12: =100-($V$6-V12) -> 100.50808 | Z12: 250.11347 | AA12: 3 | AB12: 100.6946 | AC12: =100-($AB$6-AB12) -> 100.61786
B13: 205.97029 | C13: 3.5 | D13: 99.5658 | E13: =100-($D$6-D13) -> 100.2791 | H13: 225.01489 | I13: 3.5 | J13: 96.23912 | K13: =100-($J$6-J13) -> 100.3467 | N13: 230.2874 | O13: 3.5 | P13: 100.23308 | Q13: =100-($P$6-P13) -> 100.36866 | T13: 249.99692 | U13: 3.5 | V13: 96.37281 | W13: =100-($V$6-V13) -> 100.53021 | Z13: 250.08651 | AA13: 3.5 | AB13: 100.85159 | AC13: =100-($AB$6-AB13) -> 100.77485
B14: 205.87992 | C14: 4 | D14: 99.52699 | E14: =100-($D$6-D14) -> 100.24029 | H14: 224.9908 | I14: 4 | J14: 96.25166 | K14: =100-($J$6-J14) -> 100.35924 | N14: 230.20675 | O14: 4 | P14: 100.22795 | Q14: =100-($P$6-P14) -> 100.36353 | T14: 249.95792 | U14: 4 | V14: 96.38665 | W14: =100-($V$6-V14) -> 100.54405 | Z14: 250.0679 | AA14: 4 | AB14: 100.84871 | AC14: =100-($AB$6-AB14) -> 100.77197
B15: 205.72739 | C15: 4.5 | D15: 99.49221 | E15: =100-($D$6-D15) -> 100.20551 | H15: 224.97685 | I15: 4.5 | J15: 96.24643 | K15: =100-($J$6-J15) -> 100.35401 | N15: 230.06839 | O15: 4.5 | P15: 100.39991 | Q15: =100-($P$6-P15) -> 100.53549 | T15: 249.94597 | U15: 4.5 | V15: 96.40255 | W15: =100-($V$6-V15) -> 100.55995 | Z15: 250.05477 | AA15: 4.5 | AB15: 100.79655 | AC15: =100-($AB$6-AB15) -> 100.71981
B16: 205.50274 | C16: 5 | D16: 99.55578 | E16: =100-($D$6-D16) -> 100.26908 | H16: 224.96697 | I16: 5 | J16: 96.25544 | K16: =100-($J$6-J16) -> 100.36302 | N16: 229.85206 | O16: 5 | P16: 100.21492 | Q16: =100-($P$6-P16) -> 100.3505 | T16: 249.94298 | U16: 5 | V16: 96.42681 | W16: =100-($V$6-V16) -> 100.58421 | Z16: 250.04676 | AA16: 5 | AB16: 100.89208 | AC16: =100-($AB$6-AB16) -> 100.81534
B17: 205.20155 | C17: 5.5 | D17: 99.59917 | E17: =100-($D$6-D17) -> 100.31247 | H17: 224.968 | I17: 5.5 | J17: 96.28191 | K17: =100-($J$6-J17) -> 100.38949 | N17: 229.57033 | O17: 5.5 | P17: 100.21313 | Q17: =100-($P$6-P17) -> 100.34871 | T17: 249.94199 | U17: 5.5 | V17: 96.43915 | W17: =100-($V$6-V17) -> 100.59655 | Z17: 250.03738 | AA17: 5.5 | AB17: 100.87633 | AC17: =100-($AB$6-AB17) -> 100.79959
... B485: 200.01536 | C485: 239.5 | D485: 100.16836 | E485: =100-($D$6-D485) -> 100.88166 | H485: 225.00789 | I485: 239.5 | J485: 93.39655 | K485: =100-($J$6-J485) -> 97.50413 | N485: 225.01836 | O485: 239.5 | P485: 100.29863 | Q485: =100-($P$6-P485) -> 100.43421 | T485: 250.004 | U485: 239.5 | V485: 90.52447 | W485: =100-($V$6-V485) -> 94.68187 | Z485: 250.01695 | AA485: 239.5 | AB485: 98.46326 | AC485: =100-($AB$6-AB485) -> 98.38652
T486: 249.99897 | U486: 240 | V486: 90.51644 | W486: =100-($V$6-V486) -> 94.67384 | Z486: 250.01919 | AA486: 240 | AB486: 98.57901 | AC486: =100-($AB$6-AB486) -> 98.50227
T487: 250.00899 | U487: 240.5 | V487: 90.52835 | W487: =100-($V$6-V487) -> 94.68575 | Z487: 250.015 | AA487: 240.5 | AB487: 98.5855 | AC487: =100-($AB$6-AB487) -> 98.50876
T488: 250.00904 | U488: 241 | V488: 90.51645 | W488: =100-($V$6-V488) -> 94.67385 | Z488: 250.01156 | AA488: 241 | AB488: 98.45214 | AC488: =100-($AB$6-AB488) -> 98.3754
T489: 250.00602 | U489: 241.5 | V489: 90.48622 | W489: =100-($V$6-V489) -> 94.64362 | Z489: 250.01096 | AA489: 241.5 | AB489: 98.53056 | AC489: =100-($AB$6-AB489) -> 98.45382
T490: 249.99702 | U490: 242 | V490: 90.46637 | W490: =100-($V$6-V490) -> 94.62377 | Z490: 250.01141 | AA490: 242 | AB490: 98.47909 | AC490: =100-($AB$6-AB490) -> 98.40235
T491: 250.00297 | U491: 242.5 | V491: 90.45618 | W491: =100-($V$6-V491) -> 94.61358 | Z491: 250.00971 | AA491: 242.5 | AB491: 98.3413 | AC491: =100-($AB$6-AB491) -> 98.26456
T492: 250.00297 | U492: 243 | V492: 90.44817 | W492: =100-($V$6-V492) -> 94.60557 | Z492: 250.01232 | AA492: 243 | AB492: 98.45931 | AC492: =100-($AB$6-AB492) -> 98.38257
T493: 250.00802 | U493: 243.5 | V493: 90.43809 | W493: =100-($V$6-V493) -> 94.59549 | Z493: 250.01966 | AA493: 243.5 | AB493: 98.31673 | AC493: =100-($AB$6-AB493) -> 98.23999
T494: 250.00903 | U494: 244 | V494: 90.43621 | W494: =100-($V$6-V494) -> 94.59361 | Z494: 250.0215 | AA494: 244 | AB494: 98.42617 | AC494: =100-($AB$6-AB494) -> 98.34943
T495: 250.00699 | U495: 244.5 | V495: 90.41804 | W495: =100-($V$6-V495) -> 94.57544 | Z495: 250.01781 | AA495: 244.5 | AB495: 98.36693 | AC495: =100-($AB$6-AB495) -> 98.29019
T496: 250.00391 | U496: 245 | V496: 90.40211 | W496: =100-($V$6-V496) -> 94.55951 | Z496: 250.0178 | AA496: 245 | AB496: 98.39789 | AC496: =100-($AB$6-AB496) -> 98.32115
T497: 250 | U497: 245.5 | V497: 90.38604 | W497: =100-($V$6-V497) -> 94.54344 | Z497: 250.0186 | AA497: 245.5 | AB497: 98.38818 | AC497: =100-($AB$6-AB497) -> 98.31144
... T1205: 250.00803 | U1205: 599.5 | V1205: 83.33807 | W1205: =100-($V$6-V1205) -> 87.49547 | Z1205: 250.00981 | AA1205: 599.5 | AB1205: 93.82132 | AC1205: =100-($AB$6-AB1205) -> 93.74458

Sheet Graphing
V34: Diff:
V35: ='All Data'!Q485-'All Data'!K485 -> 2.93008
V52: Diff=
V53: ='All Data'!AC1205-'All Data'!W1205 -> 6.24911 | W53: %

Sheet 200C (Odin)
A1: #EXPORTTYPE: | B1: DATA ALL
A2: #FILE: | B2: WS 500C.ngb-ds1
A3: #FORMAT: | B3: NETZSCH5
A4: #FTYPE: | B4: UNICODE
A5: #IDENTITY: | B5: WS 500C
A6: #MTYPE: | B6: DSC
A7: #INSTRUMENT: | B7: NETZSCH STA 449F1
A8: #PROJECT: | B8: 113397
A9: #DATE/TIME: | B9: 30-10-2025 23:13:54 (UTC+1)
A10: #CORR. FILE: | B10: Correction for method ISOTHERMAL 200C, 20% O2, 30MIN DRYING TIME
A11: #TEMPCAL: | B11: TCALZERO.TCX
A12: #SENSITIVITY: | B12: SENSZERO.EXX
A13: #LABORATORY: | B13: CHEC-053
A14: #OPERATOR: | B14: cornelius
A15: #REMARK:
A16: #SAMPLE: | B16: WS 500C
A17: #SAMPLE MASS /mg: | B17: 4.797775
A18: #MATERIAL: | B18: biochar
A19: #REFERENCE: | B19: ahugo
A20: #REFERENCE MASS /mg: | B20: 0
A21: #TYPE OF CRUCIBLE: | B21: Al2O3 85 µl, open
A22: #SAMPLE CRUCIBLE MASS /mg: | B22: 145.14855
A23: #REFERENCE CRUCIBLE MASS /mg: | B23: 144.16
A24: #PURGE 1 MFC: | B24: OXYGEN,252,5 ml/min
A25: #PURGE 2 MFC: | B25: NITROGEN,250,0 ml/min
A26: #PROTECTIVE MFC: | B26: NITROGEN,250,0 ml/min
A27: #DSC RANGE /µV: | B27: 5000
A28: #TG RANGE /mg: | B28: 5000
A29: #TAU-R: | B29: ---
A30: #CORR. CODE: | B30: 20
A31: #EXO: | B31: 1
A32: #RANGE: | B32: 50°C....200°C/0.0....40.0K/min
A33: #SEGMENT: | B33: S1-4/4
A34: #SEG. 1: | B34: 50°C/40.0(K/min)/105°C
A35: #SEG. 2: | B35: 105°C/00:30/105°C
A36: #SEG. 3: | B36: 105°C/5.0(K/min)/200°C
A37: #SEG. 4: | B37: 200°C/04:00/200°C
A39: ##Temp./°C | B39: Time/min | C39: DSC/(uV/mg) | D39: Mass/% | E39: Gas Flow(purge1)/(ml/min) | F39: Gas Flow(protective)/(ml/min) | G39: Sensit./(uV/mW) | H39: Segment | I39: X_C | J39: Column1 | N39: =MAX(D141:D620) -> 100.31329
A40: 45.775 | B40: 0 | C40: 0.02019547 | D40: 100 | E40: 0 | F40: 100 | G40: 1 | H40: 1
A41: 46.72136 | B41: 0.5 | C41: 0.09413953 | D41: 100.13652 | E41: 0 | F41: 100 | G41: 1 | H41: 1
...

Sheet 225C (Sif)
A1: #EXPORTTYPE: | B1: DATA SINGLE
A2: #FILE: | B2: WS.ngb-dt6
A3: #FORMAT: | B3: NETZSCH5
A4: #FTYPE: | B4: UNICODE
A5: #IDENTITY: | B5: WS
A6: #MTYPE: | B6: TG
A7: #INSTRUMENT: | B7: NETZSCH TG 209F3
A8: #PROJECT: | B8: 113397
A9: #DATE/TIME: | B9: 04-11-2025 02:40:05 (UTC+1)
A10: #CORR. FILE: | B10: Correction for method ISOTHERMAL OX 225 20% O2 4H
A11: #TEMPCAL: | B11: TCALZERO.TCX
A12: #LABORATORY: | B12: 53
A13: #OPERATOR: | B13: ahugo
A14: #REMARK: | B14: Initial mass: 4,738
A15: #SAMPLE: | B15: WS
A16: #SAMPLE MASS /mg: | B16: 4.7378
A17: #MATERIAL: | B17: BLANK
A18: #TYPE OF CRUCIBLE: | B18: Al2O3 85 µl, open
A19: #SAMPLE CRUCIBLE MASS /mg: | B19: 144.9061
A20: #REFERENCE CRUCIBLE MASS /mg:
A21: #M.RANGE /mg: | B21: 2000
A22: #CORR. CODE: | B22: 20
A23: #RANGE: | B23: 45°C....225°C/0.0....20.0K/min
A24: #SEGMENT: | B24: S1-5/5
A25: #SEG. 1: | B25: 45°C/20.0(K/min)/105°C
A26: #SEG. 2: | B26: 105°C/00:30/105°C
A27: #SEG. 3: | B27: 105°C/5.0(K/min)/225°C
A28: #SEG. 4: | B28: 225°C/00:30/225°C | J28: 17.280886
A29: #SEG. 5: | B29: 225°C/04:00/225°C
H30: =MAX(C205:C684) -> 96.28792 | I30: m0 * (1-ash)
A31: ##Temp./°C | B31: Time/min | C31: Mass/% | D31: Segment | E31: X_C | I31: =H30*(1-J28/100) -> 79.648515
A32: 47.871 | B32: 0.5 | C32: 99.96412 | D32: 1
A33: 53.566 | B33: 1 | C33: 99.94934 | D33: 1
A34: 61.289 | B34: 1.5 | C34: 99.89869 | D34: 1
A35: 70.648 | B35: 2 | C35: 99.79737 | D35: 1
A36: 81.043 | B36: 2.5 | C36: 99.67918 | D36: 1
A37: 92.07991 | B37: 3 | C37: 99.53818 | D37: 2
A38: 101.27861 | B38: 3.5 | C38: 99.27603 | D38: 2
A39: 106.38947 | B39: 4 | C39: 99.17752 | D39: 2
A40: 108.86304 | B40: 4.5 | C40: 99.03844 | D40: 2
...

Sheet 225C (Odin)
A1: #EXPORTTYPE: | B1: DATA ALL
A2: #FILE: | B2: WS500.ngb-ds1
A3: #FORMAT: | B3: NETZSCH5
A4: #FTYPE: | B4: UNICODE
A5: #IDENTITY: | B5: WS500
A6: #MTYPE: | B6: DSC
A7: #INSTRUMENT: | B7: NETZSCH STA 449F1
A8: #PROJECT: | B8: 113397
A9: #DATE/TIME: | B9: 13-11-2025 02:12:49 (UTC+1)
A10: #CORR. FILE: | B10: Correction for method 225C 20% O2, ISOTHERMAL 4H
A11: #TEMPCAL: | B11: TCALZERO.TCX
A12: #SENSITIVITY: | B12: SENSZERO.EXX
A13: #LABORATORY: | B13: CHEC-053
A14: #OPERATOR: | B14: AHUGO, CORNELIUS
A15: #REMARK:
A16: #SAMPLE: | B16: WS500
A17: #SAMPLE MASS /mg: | B17: 4.51745
A18: #MATERIAL: | B18: biochar
A19: #REFERENCE: | B19: ahugo
A20: #REFERENCE MASS /mg: | B20: 0
A21: #TYPE OF CRUCIBLE: | B21: Al2O3 85 µl, open
A22: #SAMPLE CRUCIBLE MASS /mg: | B22: 141.77947
A23: #REFERENCE CRUCIBLE MASS /mg: | B23: 143.75
A24: #PURGE 1 MFC: | B24: OXYGEN,252,5 ml/min
A25: #PURGE 2 MFC: | B25: NITROGEN,250,0 ml/min
A26: #PROTECTIVE MFC: | B26: NITROGEN,250,0 ml/min
A27: #DSC RANGE /µV: | B27: 5000
A28: #TG RANGE /mg: | B28: 5000
A29: #TAU-R: | B29: ---
A30: #CORR. CODE: | B30: 20
A31: #EXO: | B31: 1
A32: #RANGE: | B32: 50°C....225°C/0.0....40.0K/min
A33: #SEGMENT: | B33: S1-4/4
A34: #SEG. 1: | B34: 50°C/40.0(K/min)/105°C
A35: #SEG. 2: | B35: 105°C/00:30/105°C | J35: Max Point Isothermal:
A36: #SEG. 3: | B36: 105°C/5.0(K/min)/225°C | J36: =MAX(D103:D630) -> 100.87651
A37: #SEG. 4: | B37: 225°C/04:00/225°C
A39: ##Temp./°C | B39: Time/min | C39: DSC/(uV/mg) | D39: Mass/% | E39: Gas Flow(purge1)/(ml/min) | F39: Gas Flow(protective)/(ml/min) | G39: Sensit./(uV/mW) | H39: Segment | I39: X_C | J39: Column1
A40: 50.868 | B40: 0 | C40: -0.02279977 | D40: 100 | E40: 0 | F40: 100 | G40: 1 | H40: 1
A41: 51.09036 | B41: 0.5 | C41: 0.04914619 | D41: 100.13282 | E41: 0 | F41: 100 | G41: 1 | H41: 1
...

Sheet 250C (Sif)
A1: #EXPORTTYPE: | B1: DATA SINGLE
A2: #FILE: | B2: WS500.ngb-dt6
A3: #FORMAT: | B3: NETZSCH5
A4: #FTYPE: | B4: UNICODE
A5: #IDENTITY: | B5: WS500
A6: #MTYPE: | B6: TG
A7: #INSTRUMENT: | B7: NETZSCH TG 209F3
A8: #PROJECT: | B8: 113397
A9: #DATE/TIME: | B9: 01-11-2025 11:59:41 (UTC+1)
A10: #CORR. FILE: | B10: Correction for method CHAR ISOTHERMAL 10H 250C 20% O2
A11: #TEMPCAL: | B11: TCALZERO.TCX
A12: #LABORATORY: | B12: 53
A13: #OPERATOR: | B13: ahugo
A14: #REMARK: | B14: Initial mass: 4,984
A15: #SAMPLE: | B15: WS500
A16: #SAMPLE MASS /mg: | B16: 4.9844
A17: #MATERIAL: | B17: empty
A18: #TYPE OF CRUCIBLE: | B18: Al2O3 85 µl, open
A19: #SAMPLE CRUCIBLE MASS /mg: | B19: 144.7566
A20: #REFERENCE CRUCIBLE MASS /mg:
A21: #M.RANGE /mg: | B21: 2000
A22: #CORR. CODE: | B22: 20
A23: #RANGE: | B23: 45°C....250°C/0.0....40.0K/min
A24: #SEGMENT: | B24: S1-5/5
A25: #SEG. 1: | B25: 45°C/40.0(K/min)/105°C
A26: #SEG. 2: | B26: 105°C/00:30/105°C
A27: #SEG. 3: | B27: 105°C/5.0(K/min)/250°C
A28: #SEG. 4: | B28: 250°C/00:30/250°C
A29: #SEG. 5: | B29: 250°C/10:00/250°C
A31: ##Temp./°C | B31: Time/min | C31: Mass/% | D31: Segment | E31: X_C | I31: =MAX(C212:C1411) -> 96.47508
A32: 50.621 | B32: 0.5 | C32: 100.04815 | D32: 1
A33: 62.413 | B33: 1 | C33: 99.94583 | D33: 1
A34: 78.79068 | B34: 1.5 | C34: 99.79608 | D34: 2
A35: 94.29439 | B35: 2 | C35: 99.53626 | D35: 2
A36: 103.11173 | B36: 2.5 | C36: 99.3535 | D36: 2
A37: 107.74029 | B37: 3 | C37: 99.19534 | D37: 2
A38: 109.78288 | B38: 3.5 | C38: 99.07892 | D38: 2
A39: 110.26891 | B39: 4 | C39: 99.0029 | D39: 2
A40: 109.88389 | B40: 4.5 | C40: 98.95064 | D40: 2
A41: 109.08945 | B41: 5 | C41: 98.90851 | D41: 2
...

Sheet 250C (Odin)
A1: #EXPORTTYPE: | B1: DATA ALL
A2: #FILE: | B2: WS500.ngb-ds1
A3: #FORMAT: | B3: NETZSCH5
A4: #FTYPE: | B4: UNICODE
A5: #IDENTITY: | B5: WS500
A6: #MTYPE: | B6: DSC
A7: #INSTRUMENT: | B7: NETZSCH STA 449F1
A8: #PROJECT: | B8: 113397
A9: #DATE/TIME: | B9: 15-11-2025 18:03:55 (UTC+1)
A10: #CORR. FILE: | B10: Correction for method ISOTHERMAL 250C 20% O2 10H HOLD
A11: #TEMPCAL: | B11: TCALZERO.TCX
A12: #SENSITIVITY: | B12: SENSZERO.EXX
A13: #LABORATORY: | B13: CHEC-053
A14: #OPERATOR: | B14: CORNELIUS
A15: #REMARK:
A16: #SAMPLE: | B16: WS500
A17: #SAMPLE MASS /mg: | B17: 4.91565
A18: #MATERIAL: | B18: empty
A19: #REFERENCE: | B19: ahugo
A20: #REFERENCE MASS /mg: | B20: 0
A21: #TYPE OF CRUCIBLE: | B21: Al2O3 85 µl, open
A22: #SAMPLE CRUCIBLE MASS /mg: | B22: 143.50405
A23: #REFERENCE CRUCIBLE MASS /mg: | B23: 143.75
A24: #PURGE 1 MFC: | B24: OXYGEN,252,5 ml/min
A25: #PURGE 2 MFC: | B25: NITROGEN,250,0 ml/min
A26: #PROTECTIVE MFC: | B26: NITROGEN,250,0 ml/min
A27: #DSC RANGE /µV: | B27: 5000
A28: #TG RANGE /mg: | B28: 5000
A29: #TAU-R: | B29: ---
A30: #CORR. CODE: | B30: 20
A31: #EXO: | B31: 1
A32: #RANGE: | B32: 45°C....250°C/0.0....40.0K/min
A33: #SEGMENT: | B33: S1-5/5
A34: #SEG. 1: | B34: 45°C/40.0(K/min)/110°C
A35: #SEG. 2: | B35: 110°C/00:30/110°C
A36: #SEG. 3: | B36: 110°C/5.0(K/min)/250°C
A37: #SEG. 4: | B37: 250°C/00:30/250°C
A38: #SEG. 5: | B38: 250°C/10:00/250°C
A40: ##Temp./°C | B40: Time/min | C40: DSC/(uV/mg) | D40: Mass/% | E40: Gas Flow(purge1)/(ml/min) | F40: Gas Flow(protective)/(ml/min) | G40: Sensit./(uV/mW) | H40: Segment
A41: 45.759 | B41: 0 | C41: -0.02685068 | D41: 100 | E41: 0 | F41: 100 | G41: 1 | H41: 1
...
